2020-02-28 11:12 transito     ERROR    (pymysql.err.OperationalError) (1044, "Access denied for user 'ivan'@'%' to database 'transito'")
(Background on this error at: http://sqlalche.me/e/e3q8)
Traceback (most recent call last):
  File "/home/ivan/PycharmProjects/transito/venv/lib/python3.6/site-packages/sqlalchemy/engine/base.py", line 2276, in _wrap_pool_connect
    return fn()
  File "/home/ivan/PycharmProjects/transito/venv/lib/python3.6/site-packages/sqlalchemy/pool/base.py", line 363, in connect
    return _ConnectionFairy._checkout(self)
  File "/home/ivan/PycharmProjects/transito/venv/lib/python3.6/site-packages/sqlalchemy/pool/base.py", line 773, in _checkout
    fairy = _ConnectionRecord.checkout(pool)
  File "/home/ivan/PycharmProjects/transito/venv/lib/python3.6/site-packages/sqlalchemy/pool/base.py", line 492, in checkout
    rec = pool._do_get()
  File "/home/ivan/PycharmProjects/transito/venv/lib/python3.6/site-packages/sqlalchemy/pool/impl.py", line 139, in _do_get
    self._dec_overflow()
  File "/home/ivan/PycharmProjects/transito/venv/lib/python3.6/site-packages/sqlalchemy/util/langhelpers.py", line 68, in __exit__
    compat.reraise(exc_type, exc_value, exc_tb)
  File "/home/ivan/PycharmProjects/transito/venv/lib/python3.6/site-packages/sqlalchemy/util/compat.py", line 153, in reraise
    raise value
  File "/home/ivan/PycharmProjects/transito/venv/lib/python3.6/site-packages/sqlalchemy/pool/impl.py", line 136, in _do_get
    return self._create_connection()
  File "/home/ivan/PycharmProjects/transito/venv/lib/python3.6/site-packages/sqlalchemy/pool/base.py", line 308, in _create_connection
    return _ConnectionRecord(self)
  File "/home/ivan/PycharmProjects/transito/venv/lib/python3.6/site-packages/sqlalchemy/pool/base.py", line 437, in __init__
    self.__connect(first_connect_check=True)
  File "/home/ivan/PycharmProjects/transito/venv/lib/python3.6/site-packages/sqlalchemy/pool/base.py", line 652, in __connect
    connection = pool._invoke_creator(self)
  File "/home/ivan/PycharmProjects/transito/venv/lib/python3.6/site-packages/sqlalchemy/engine/strategies.py", line 114, in connect
    return dialect.connect(*cargs, **cparams)
  File "/home/ivan/PycharmProjects/transito/venv/lib/python3.6/site-packages/sqlalchemy/engine/default.py", line 489, in connect
    return self.dbapi.connect(*cargs, **cparams)
  File "/home/ivan/PycharmProjects/transito/venv/lib/python3.6/site-packages/pymysql/__init__.py", line 94, in Connect
    return Connection(*args, **kwargs)
  File "/home/ivan/PycharmProjects/transito/venv/lib/python3.6/site-packages/pymysql/connections.py", line 325, in __init__
    self.connect()
  File "/home/ivan/PycharmProjects/transito/venv/lib/python3.6/site-packages/pymysql/connections.py", line 599, in connect
    self._request_authentication()
  File "/home/ivan/PycharmProjects/transito/venv/lib/python3.6/site-packages/pymysql/connections.py", line 861, in _request_authentication
    auth_packet = self._read_packet()
  File "/home/ivan/PycharmProjects/transito/venv/lib/python3.6/site-packages/pymysql/connections.py", line 684, in _read_packet
    packet.check_error()
  File "/home/ivan/PycharmProjects/transito/venv/lib/python3.6/site-packages/pymysql/protocol.py", line 220, in check_error
    err.raise_mysql_exception(self._data)
  File "/home/ivan/PycharmProjects/transito/venv/lib/python3.6/site-packages/pymysql/err.py", line 109, in raise_mysql_exception
    raise errorclass(errno, errval)
pymysql.err.OperationalError: (1044, "Access denied for user 'ivan'@'%' to database 'transito'")

The above exception was the direct cause of the following exception:

Traceback (most recent call last):
  File "/home/ivan/PycharmProjects/transito/transito/routes/dta.py", line 18, in transito
    listaanexos = lista_anexos(session, dta_id)
  File "/home/ivan/PycharmProjects/transito/transito/models/dtamanager.py", line 15, in lista_anexos
    return session.query(Anexo).filter(Anexo.dta_id == dta_id).all()
  File "/home/ivan/PycharmProjects/transito/venv/lib/python3.6/site-packages/sqlalchemy/orm/query.py", line 3233, in all
    return list(self)
  File "/home/ivan/PycharmProjects/transito/venv/lib/python3.6/site-packages/sqlalchemy/orm/query.py", line 3389, in __iter__
    return self._execute_and_instances(context)
  File "/home/ivan/PycharmProjects/transito/venv/lib/python3.6/site-packages/sqlalchemy/orm/query.py", line 3411, in _execute_and_instances
    querycontext, self._connection_from_session, close_with_result=True
  File "/home/ivan/PycharmProjects/transito/venv/lib/python3.6/site-packages/sqlalchemy/orm/query.py", line 3426, in _get_bind_args
    mapper=self._bind_mapper(), clause=querycontext.statement, **kw
  File "/home/ivan/PycharmProjects/transito/venv/lib/python3.6/site-packages/sqlalchemy/orm/query.py", line 3404, in _connection_from_session
    conn = self.session.connection(**kw)
  File "/home/ivan/PycharmProjects/transito/venv/lib/python3.6/site-packages/sqlalchemy/orm/session.py", line 1133, in connection
    execution_options=execution_options,
  File "/home/ivan/PycharmProjects/transito/venv/lib/python3.6/site-packages/sqlalchemy/orm/session.py", line 1139, in _connection_for_bind
    engine, execution_options
  File "/home/ivan/PycharmProjects/transito/venv/lib/python3.6/site-packages/sqlalchemy/orm/session.py", line 432, in _connection_for_bind
    conn = bind._contextual_connect()
  File "/home/ivan/PycharmProjects/transito/venv/lib/python3.6/site-packages/sqlalchemy/engine/base.py", line 2242, in _contextual_connect
    self._wrap_pool_connect(self.pool.connect, None),
  File "/home/ivan/PycharmProjects/transito/venv/lib/python3.6/site-packages/sqlalchemy/engine/base.py", line 2280, in _wrap_pool_connect
    e, dialect, self
  File "/home/ivan/PycharmProjects/transito/venv/lib/python3.6/site-packages/sqlalchemy/engine/base.py", line 1547, in _handle_dbapi_exception_noconnection
    util.raise_from_cause(sqlalchemy_exception, exc_info)
  File "/home/ivan/PycharmProjects/transito/venv/lib/python3.6/site-packages/sqlalchemy/util/compat.py", line 398, in raise_from_cause
    reraise(type(exception), exception, tb=exc_tb, cause=cause)
  File "/home/ivan/PycharmProjects/transito/venv/lib/python3.6/site-packages/sqlalchemy/util/compat.py", line 152, in reraise
    raise value.with_traceback(tb)
  File "/home/ivan/PycharmProjects/transito/venv/lib/python3.6/site-packages/sqlalchemy/engine/base.py", line 2276, in _wrap_pool_connect
    return fn()
  File "/home/ivan/PycharmProjects/transito/venv/lib/python3.6/site-packages/sqlalchemy/pool/base.py", line 363, in connect
    return _ConnectionFairy._checkout(self)
  File "/home/ivan/PycharmProjects/transito/venv/lib/python3.6/site-packages/sqlalchemy/pool/base.py", line 773, in _checkout
    fairy = _ConnectionRecord.checkout(pool)
  File "/home/ivan/PycharmProjects/transito/venv/lib/python3.6/site-packages/sqlalchemy/pool/base.py", line 492, in checkout
    rec = pool._do_get()
  File "/home/ivan/PycharmProjects/transito/venv/lib/python3.6/site-packages/sqlalchemy/pool/impl.py", line 139, in _do_get
    self._dec_overflow()
  File "/home/ivan/PycharmProjects/transito/venv/lib/python3.6/site-packages/sqlalchemy/util/langhelpers.py", line 68, in __exit__
    compat.reraise(exc_type, exc_value, exc_tb)
  File "/home/ivan/PycharmProjects/transito/venv/lib/python3.6/site-packages/sqlalchemy/util/compat.py", line 153, in reraise
    raise value
  File "/home/ivan/PycharmProjects/transito/venv/lib/python3.6/site-packages/sqlalchemy/pool/impl.py", line 136, in _do_get
    return self._create_connection()
  File "/home/ivan/PycharmProjects/transito/venv/lib/python3.6/site-packages/sqlalchemy/pool/base.py", line 308, in _create_connection
    return _ConnectionRecord(self)
  File "/home/ivan/PycharmProjects/transito/venv/lib/python3.6/site-packages/sqlalchemy/pool/base.py", line 437, in __init__
    self.__connect(first_connect_check=True)
  File "/home/ivan/PycharmProjects/transito/venv/lib/python3.6/site-packages/sqlalchemy/pool/base.py", line 652, in __connect
    connection = pool._invoke_creator(self)
  File "/home/ivan/PycharmProjects/transito/venv/lib/python3.6/site-packages/sqlalchemy/engine/strategies.py", line 114, in connect
    return dialect.connect(*cargs, **cparams)
  File "/home/ivan/PycharmProjects/transito/venv/lib/python3.6/site-packages/sqlalchemy/engine/default.py", line 489, in connect
    return self.dbapi.connect(*cargs, **cparams)
  File "/home/ivan/PycharmProjects/transito/venv/lib/python3.6/site-packages/pymysql/__init__.py", line 94, in Connect
    return Connection(*args, **kwargs)
  File "/home/ivan/PycharmProjects/transito/venv/lib/python3.6/site-packages/pymysql/connections.py", line 325, in __init__
    self.connect()
  File "/home/ivan/PycharmProjects/transito/venv/lib/python3.6/site-packages/pymysql/connections.py", line 599, in connect
    self._request_authentication()
  File "/home/ivan/PycharmProjects/transito/venv/lib/python3.6/site-packages/pymysql/connections.py", line 861, in _request_authentication
    auth_packet = self._read_packet()
  File "/home/ivan/PycharmProjects/transito/venv/lib/python3.6/site-packages/pymysql/connections.py", line 684, in _read_packet
    packet.check_error()
  File "/home/ivan/PycharmProjects/transito/venv/lib/python3.6/site-packages/pymysql/protocol.py", line 220, in check_error
    err.raise_mysql_exception(self._data)
  File "/home/ivan/PycharmProjects/transito/venv/lib/python3.6/site-packages/pymysql/err.py", line 109, in raise_mysql_exception
    raise errorclass(errno, errval)
sqlalchemy.exc.OperationalError: (pymysql.err.OperationalError) (1044, "Access denied for user 'ivan'@'%' to database 'transito'")
(Background on this error at: http://sqlalche.me/e/e3q8)
2020-02-28 11:12 transito     ERROR    (pymysql.err.OperationalError) (1044, "Access denied for user 'ivan'@'%' to database 'transito'")
(Background on this error at: http://sqlalche.me/e/e3q8)
Traceback (most recent call last):
  File "/home/ivan/PycharmProjects/transito/venv/lib/python3.6/site-packages/sqlalchemy/engine/base.py", line 2276, in _wrap_pool_connect
    return fn()
  File "/home/ivan/PycharmProjects/transito/venv/lib/python3.6/site-packages/sqlalchemy/pool/base.py", line 363, in connect
    return _ConnectionFairy._checkout(self)
  File "/home/ivan/PycharmProjects/transito/venv/lib/python3.6/site-packages/sqlalchemy/pool/base.py", line 773, in _checkout
    fairy = _ConnectionRecord.checkout(pool)
  File "/home/ivan/PycharmProjects/transito/venv/lib/python3.6/site-packages/sqlalchemy/pool/base.py", line 492, in checkout
    rec = pool._do_get()
  File "/home/ivan/PycharmProjects/transito/venv/lib/python3.6/site-packages/sqlalchemy/pool/impl.py", line 139, in _do_get
    self._dec_overflow()
  File "/home/ivan/PycharmProjects/transito/venv/lib/python3.6/site-packages/sqlalchemy/util/langhelpers.py", line 68, in __exit__
    compat.reraise(exc_type, exc_value, exc_tb)
  File "/home/ivan/PycharmProjects/transito/venv/lib/python3.6/site-packages/sqlalchemy/util/compat.py", line 153, in reraise
    raise value
  File "/home/ivan/PycharmProjects/transito/venv/lib/python3.6/site-packages/sqlalchemy/pool/impl.py", line 136, in _do_get
    return self._create_connection()
  File "/home/ivan/PycharmProjects/transito/venv/lib/python3.6/site-packages/sqlalchemy/pool/base.py", line 308, in _create_connection
    return _ConnectionRecord(self)
  File "/home/ivan/PycharmProjects/transito/venv/lib/python3.6/site-packages/sqlalchemy/pool/base.py", line 437, in __init__
    self.__connect(first_connect_check=True)
  File "/home/ivan/PycharmProjects/transito/venv/lib/python3.6/site-packages/sqlalchemy/pool/base.py", line 652, in __connect
    connection = pool._invoke_creator(self)
  File "/home/ivan/PycharmProjects/transito/venv/lib/python3.6/site-packages/sqlalchemy/engine/strategies.py", line 114, in connect
    return dialect.connect(*cargs, **cparams)
  File "/home/ivan/PycharmProjects/transito/venv/lib/python3.6/site-packages/sqlalchemy/engine/default.py", line 489, in connect
    return self.dbapi.connect(*cargs, **cparams)
  File "/home/ivan/PycharmProjects/transito/venv/lib/python3.6/site-packages/pymysql/__init__.py", line 94, in Connect
    return Connection(*args, **kwargs)
  File "/home/ivan/PycharmProjects/transito/venv/lib/python3.6/site-packages/pymysql/connections.py", line 325, in __init__
    self.connect()
  File "/home/ivan/PycharmProjects/transito/venv/lib/python3.6/site-packages/pymysql/connections.py", line 599, in connect
    self._request_authentication()
  File "/home/ivan/PycharmProjects/transito/venv/lib/python3.6/site-packages/pymysql/connections.py", line 861, in _request_authentication
    auth_packet = self._read_packet()
  File "/home/ivan/PycharmProjects/transito/venv/lib/python3.6/site-packages/pymysql/connections.py", line 684, in _read_packet
    packet.check_error()
  File "/home/ivan/PycharmProjects/transito/venv/lib/python3.6/site-packages/pymysql/protocol.py", line 220, in check_error
    err.raise_mysql_exception(self._data)
  File "/home/ivan/PycharmProjects/transito/venv/lib/python3.6/site-packages/pymysql/err.py", line 109, in raise_mysql_exception
    raise errorclass(errno, errval)
pymysql.err.OperationalError: (1044, "Access denied for user 'ivan'@'%' to database 'transito'")

The above exception was the direct cause of the following exception:

Traceback (most recent call last):
  File "/home/ivan/PycharmProjects/transito/transito/routes/dta.py", line 18, in transito
    listaanexos = lista_anexos(session, dta_id)
  File "/home/ivan/PycharmProjects/transito/transito/models/dtamanager.py", line 15, in lista_anexos
    return session.query(Anexo).filter(Anexo.dta_id == dta_id).all()
  File "/home/ivan/PycharmProjects/transito/venv/lib/python3.6/site-packages/sqlalchemy/orm/query.py", line 3233, in all
    return list(self)
  File "/home/ivan/PycharmProjects/transito/venv/lib/python3.6/site-packages/sqlalchemy/orm/query.py", line 3389, in __iter__
    return self._execute_and_instances(context)
  File "/home/ivan/PycharmProjects/transito/venv/lib/python3.6/site-packages/sqlalchemy/orm/query.py", line 3411, in _execute_and_instances
    querycontext, self._connection_from_session, close_with_result=True
  File "/home/ivan/PycharmProjects/transito/venv/lib/python3.6/site-packages/sqlalchemy/orm/query.py", line 3426, in _get_bind_args
    mapper=self._bind_mapper(), clause=querycontext.statement, **kw
  File "/home/ivan/PycharmProjects/transito/venv/lib/python3.6/site-packages/sqlalchemy/orm/query.py", line 3404, in _connection_from_session
    conn = self.session.connection(**kw)
  File "/home/ivan/PycharmProjects/transito/venv/lib/python3.6/site-packages/sqlalchemy/orm/session.py", line 1133, in connection
    execution_options=execution_options,
  File "/home/ivan/PycharmProjects/transito/venv/lib/python3.6/site-packages/sqlalchemy/orm/session.py", line 1139, in _connection_for_bind
    engine, execution_options
  File "/home/ivan/PycharmProjects/transito/venv/lib/python3.6/site-packages/sqlalchemy/orm/session.py", line 432, in _connection_for_bind
    conn = bind._contextual_connect()
  File "/home/ivan/PycharmProjects/transito/venv/lib/python3.6/site-packages/sqlalchemy/engine/base.py", line 2242, in _contextual_connect
    self._wrap_pool_connect(self.pool.connect, None),
  File "/home/ivan/PycharmProjects/transito/venv/lib/python3.6/site-packages/sqlalchemy/engine/base.py", line 2280, in _wrap_pool_connect
    e, dialect, self
  File "/home/ivan/PycharmProjects/transito/venv/lib/python3.6/site-packages/sqlalchemy/engine/base.py", line 1547, in _handle_dbapi_exception_noconnection
    util.raise_from_cause(sqlalchemy_exception, exc_info)
  File "/home/ivan/PycharmProjects/transito/venv/lib/python3.6/site-packages/sqlalchemy/util/compat.py", line 398, in raise_from_cause
    reraise(type(exception), exception, tb=exc_tb, cause=cause)
  File "/home/ivan/PycharmProjects/transito/venv/lib/python3.6/site-packages/sqlalchemy/util/compat.py", line 152, in reraise
    raise value.with_traceback(tb)
  File "/home/ivan/PycharmProjects/transito/venv/lib/python3.6/site-packages/sqlalchemy/engine/base.py", line 2276, in _wrap_pool_connect
    return fn()
  File "/home/ivan/PycharmProjects/transito/venv/lib/python3.6/site-packages/sqlalchemy/pool/base.py", line 363, in connect
    return _ConnectionFairy._checkout(self)
  File "/home/ivan/PycharmProjects/transito/venv/lib/python3.6/site-packages/sqlalchemy/pool/base.py", line 773, in _checkout
    fairy = _ConnectionRecord.checkout(pool)
  File "/home/ivan/PycharmProjects/transito/venv/lib/python3.6/site-packages/sqlalchemy/pool/base.py", line 492, in checkout
    rec = pool._do_get()
  File "/home/ivan/PycharmProjects/transito/venv/lib/python3.6/site-packages/sqlalchemy/pool/impl.py", line 139, in _do_get
    self._dec_overflow()
  File "/home/ivan/PycharmProjects/transito/venv/lib/python3.6/site-packages/sqlalchemy/util/langhelpers.py", line 68, in __exit__
    compat.reraise(exc_type, exc_value, exc_tb)
  File "/home/ivan/PycharmProjects/transito/venv/lib/python3.6/site-packages/sqlalchemy/util/compat.py", line 153, in reraise
    raise value
  File "/home/ivan/PycharmProjects/transito/venv/lib/python3.6/site-packages/sqlalchemy/pool/impl.py", line 136, in _do_get
    return self._create_connection()
  File "/home/ivan/PycharmProjects/transito/venv/lib/python3.6/site-packages/sqlalchemy/pool/base.py", line 308, in _create_connection
    return _ConnectionRecord(self)
  File "/home/ivan/PycharmProjects/transito/venv/lib/python3.6/site-packages/sqlalchemy/pool/base.py", line 437, in __init__
    self.__connect(first_connect_check=True)
  File "/home/ivan/PycharmProjects/transito/venv/lib/python3.6/site-packages/sqlalchemy/pool/base.py", line 652, in __connect
    connection = pool._invoke_creator(self)
  File "/home/ivan/PycharmProjects/transito/venv/lib/python3.6/site-packages/sqlalchemy/engine/strategies.py", line 114, in connect
    return dialect.connect(*cargs, **cparams)
  File "/home/ivan/PycharmProjects/transito/venv/lib/python3.6/site-packages/sqlalchemy/engine/default.py", line 489, in connect
    return self.dbapi.connect(*cargs, **cparams)
  File "/home/ivan/PycharmProjects/transito/venv/lib/python3.6/site-packages/pymysql/__init__.py", line 94, in Connect
    return Connection(*args, **kwargs)
  File "/home/ivan/PycharmProjects/transito/venv/lib/python3.6/site-packages/pymysql/connections.py", line 325, in __init__
    self.connect()
  File "/home/ivan/PycharmProjects/transito/venv/lib/python3.6/site-packages/pymysql/connections.py", line 599, in connect
    self._request_authentication()
  File "/home/ivan/PycharmProjects/transito/venv/lib/python3.6/site-packages/pymysql/connections.py", line 861, in _request_authentication
    auth_packet = self._read_packet()
  File "/home/ivan/PycharmProjects/transito/venv/lib/python3.6/site-packages/pymysql/connections.py", line 684, in _read_packet
    packet.check_error()
  File "/home/ivan/PycharmProjects/transito/venv/lib/python3.6/site-packages/pymysql/protocol.py", line 220, in check_error
    err.raise_mysql_exception(self._data)
  File "/home/ivan/PycharmProjects/transito/venv/lib/python3.6/site-packages/pymysql/err.py", line 109, in raise_mysql_exception
    raise errorclass(errno, errval)
sqlalchemy.exc.OperationalError: (pymysql.err.OperationalError) (1044, "Access denied for user 'ivan'@'%' to database 'transito'")
(Background on this error at: http://sqlalche.me/e/e3q8)
2020-02-28 11:13 transito     ERROR    (pymysql.err.OperationalError) (1044, "Access denied for user 'ivan'@'%' to database 'transito'")
(Background on this error at: http://sqlalche.me/e/e3q8)
Traceback (most recent call last):
  File "/home/ivan/PycharmProjects/transito/venv/lib/python3.6/site-packages/sqlalchemy/engine/base.py", line 2276, in _wrap_pool_connect
    return fn()
  File "/home/ivan/PycharmProjects/transito/venv/lib/python3.6/site-packages/sqlalchemy/pool/base.py", line 363, in connect
    return _ConnectionFairy._checkout(self)
  File "/home/ivan/PycharmProjects/transito/venv/lib/python3.6/site-packages/sqlalchemy/pool/base.py", line 773, in _checkout
    fairy = _ConnectionRecord.checkout(pool)
  File "/home/ivan/PycharmProjects/transito/venv/lib/python3.6/site-packages/sqlalchemy/pool/base.py", line 492, in checkout
    rec = pool._do_get()
  File "/home/ivan/PycharmProjects/transito/venv/lib/python3.6/site-packages/sqlalchemy/pool/impl.py", line 139, in _do_get
    self._dec_overflow()
  File "/home/ivan/PycharmProjects/transito/venv/lib/python3.6/site-packages/sqlalchemy/util/langhelpers.py", line 68, in __exit__
    compat.reraise(exc_type, exc_value, exc_tb)
  File "/home/ivan/PycharmProjects/transito/venv/lib/python3.6/site-packages/sqlalchemy/util/compat.py", line 153, in reraise
    raise value
  File "/home/ivan/PycharmProjects/transito/venv/lib/python3.6/site-packages/sqlalchemy/pool/impl.py", line 136, in _do_get
    return self._create_connection()
  File "/home/ivan/PycharmProjects/transito/venv/lib/python3.6/site-packages/sqlalchemy/pool/base.py", line 308, in _create_connection
    return _ConnectionRecord(self)
  File "/home/ivan/PycharmProjects/transito/venv/lib/python3.6/site-packages/sqlalchemy/pool/base.py", line 437, in __init__
    self.__connect(first_connect_check=True)
  File "/home/ivan/PycharmProjects/transito/venv/lib/python3.6/site-packages/sqlalchemy/pool/base.py", line 652, in __connect
    connection = pool._invoke_creator(self)
  File "/home/ivan/PycharmProjects/transito/venv/lib/python3.6/site-packages/sqlalchemy/engine/strategies.py", line 114, in connect
    return dialect.connect(*cargs, **cparams)
  File "/home/ivan/PycharmProjects/transito/venv/lib/python3.6/site-packages/sqlalchemy/engine/default.py", line 489, in connect
    return self.dbapi.connect(*cargs, **cparams)
  File "/home/ivan/PycharmProjects/transito/venv/lib/python3.6/site-packages/pymysql/__init__.py", line 94, in Connect
    return Connection(*args, **kwargs)
  File "/home/ivan/PycharmProjects/transito/venv/lib/python3.6/site-packages/pymysql/connections.py", line 325, in __init__
    self.connect()
  File "/home/ivan/PycharmProjects/transito/venv/lib/python3.6/site-packages/pymysql/connections.py", line 599, in connect
    self._request_authentication()
  File "/home/ivan/PycharmProjects/transito/venv/lib/python3.6/site-packages/pymysql/connections.py", line 861, in _request_authentication
    auth_packet = self._read_packet()
  File "/home/ivan/PycharmProjects/transito/venv/lib/python3.6/site-packages/pymysql/connections.py", line 684, in _read_packet
    packet.check_error()
  File "/home/ivan/PycharmProjects/transito/venv/lib/python3.6/site-packages/pymysql/protocol.py", line 220, in check_error
    err.raise_mysql_exception(self._data)
  File "/home/ivan/PycharmProjects/transito/venv/lib/python3.6/site-packages/pymysql/err.py", line 109, in raise_mysql_exception
    raise errorclass(errno, errval)
pymysql.err.OperationalError: (1044, "Access denied for user 'ivan'@'%' to database 'transito'")

The above exception was the direct cause of the following exception:

Traceback (most recent call last):
  File "/home/ivan/PycharmProjects/transito/transito/routes/dta.py", line 18, in dta
    listaanexos = lista_anexos(session, dta_id)
  File "/home/ivan/PycharmProjects/transito/transito/models/dtamanager.py", line 15, in lista_anexos
    return session.query(Anexo).filter(Anexo.dta_id == dta_id).all()
  File "/home/ivan/PycharmProjects/transito/venv/lib/python3.6/site-packages/sqlalchemy/orm/query.py", line 3233, in all
    return list(self)
  File "/home/ivan/PycharmProjects/transito/venv/lib/python3.6/site-packages/sqlalchemy/orm/query.py", line 3389, in __iter__
    return self._execute_and_instances(context)
  File "/home/ivan/PycharmProjects/transito/venv/lib/python3.6/site-packages/sqlalchemy/orm/query.py", line 3411, in _execute_and_instances
    querycontext, self._connection_from_session, close_with_result=True
  File "/home/ivan/PycharmProjects/transito/venv/lib/python3.6/site-packages/sqlalchemy/orm/query.py", line 3426, in _get_bind_args
    mapper=self._bind_mapper(), clause=querycontext.statement, **kw
  File "/home/ivan/PycharmProjects/transito/venv/lib/python3.6/site-packages/sqlalchemy/orm/query.py", line 3404, in _connection_from_session
    conn = self.session.connection(**kw)
  File "/home/ivan/PycharmProjects/transito/venv/lib/python3.6/site-packages/sqlalchemy/orm/session.py", line 1133, in connection
    execution_options=execution_options,
  File "/home/ivan/PycharmProjects/transito/venv/lib/python3.6/site-packages/sqlalchemy/orm/session.py", line 1139, in _connection_for_bind
    engine, execution_options
  File "/home/ivan/PycharmProjects/transito/venv/lib/python3.6/site-packages/sqlalchemy/orm/session.py", line 432, in _connection_for_bind
    conn = bind._contextual_connect()
  File "/home/ivan/PycharmProjects/transito/venv/lib/python3.6/site-packages/sqlalchemy/engine/base.py", line 2242, in _contextual_connect
    self._wrap_pool_connect(self.pool.connect, None),
  File "/home/ivan/PycharmProjects/transito/venv/lib/python3.6/site-packages/sqlalchemy/engine/base.py", line 2280, in _wrap_pool_connect
    e, dialect, self
  File "/home/ivan/PycharmProjects/transito/venv/lib/python3.6/site-packages/sqlalchemy/engine/base.py", line 1547, in _handle_dbapi_exception_noconnection
    util.raise_from_cause(sqlalchemy_exception, exc_info)
  File "/home/ivan/PycharmProjects/transito/venv/lib/python3.6/site-packages/sqlalchemy/util/compat.py", line 398, in raise_from_cause
    reraise(type(exception), exception, tb=exc_tb, cause=cause)
  File "/home/ivan/PycharmProjects/transito/venv/lib/python3.6/site-packages/sqlalchemy/util/compat.py", line 152, in reraise
    raise value.with_traceback(tb)
  File "/home/ivan/PycharmProjects/transito/venv/lib/python3.6/site-packages/sqlalchemy/engine/base.py", line 2276, in _wrap_pool_connect
    return fn()
  File "/home/ivan/PycharmProjects/transito/venv/lib/python3.6/site-packages/sqlalchemy/pool/base.py", line 363, in connect
    return _ConnectionFairy._checkout(self)
  File "/home/ivan/PycharmProjects/transito/venv/lib/python3.6/site-packages/sqlalchemy/pool/base.py", line 773, in _checkout
    fairy = _ConnectionRecord.checkout(pool)
  File "/home/ivan/PycharmProjects/transito/venv/lib/python3.6/site-packages/sqlalchemy/pool/base.py", line 492, in checkout
    rec = pool._do_get()
  File "/home/ivan/PycharmProjects/transito/venv/lib/python3.6/site-packages/sqlalchemy/pool/impl.py", line 139, in _do_get
    self._dec_overflow()
  File "/home/ivan/PycharmProjects/transito/venv/lib/python3.6/site-packages/sqlalchemy/util/langhelpers.py", line 68, in __exit__
    compat.reraise(exc_type, exc_value, exc_tb)
  File "/home/ivan/PycharmProjects/transito/venv/lib/python3.6/site-packages/sqlalchemy/util/compat.py", line 153, in reraise
    raise value
  File "/home/ivan/PycharmProjects/transito/venv/lib/python3.6/site-packages/sqlalchemy/pool/impl.py", line 136, in _do_get
    return self._create_connection()
  File "/home/ivan/PycharmProjects/transito/venv/lib/python3.6/site-packages/sqlalchemy/pool/base.py", line 308, in _create_connection
    return _ConnectionRecord(self)
  File "/home/ivan/PycharmProjects/transito/venv/lib/python3.6/site-packages/sqlalchemy/pool/base.py", line 437, in __init__
    self.__connect(first_connect_check=True)
  File "/home/ivan/PycharmProjects/transito/venv/lib/python3.6/site-packages/sqlalchemy/pool/base.py", line 652, in __connect
    connection = pool._invoke_creator(self)
  File "/home/ivan/PycharmProjects/transito/venv/lib/python3.6/site-packages/sqlalchemy/engine/strategies.py", line 114, in connect
    return dialect.connect(*cargs, **cparams)
  File "/home/ivan/PycharmProjects/transito/venv/lib/python3.6/site-packages/sqlalchemy/engine/default.py", line 489, in connect
    return self.dbapi.connect(*cargs, **cparams)
  File "/home/ivan/PycharmProjects/transito/venv/lib/python3.6/site-packages/pymysql/__init__.py", line 94, in Connect
    return Connection(*args, **kwargs)
  File "/home/ivan/PycharmProjects/transito/venv/lib/python3.6/site-packages/pymysql/connections.py", line 325, in __init__
    self.connect()
  File "/home/ivan/PycharmProjects/transito/venv/lib/python3.6/site-packages/pymysql/connections.py", line 599, in connect
    self._request_authentication()
  File "/home/ivan/PycharmProjects/transito/venv/lib/python3.6/site-packages/pymysql/connections.py", line 861, in _request_authentication
    auth_packet = self._read_packet()
  File "/home/ivan/PycharmProjects/transito/venv/lib/python3.6/site-packages/pymysql/connections.py", line 684, in _read_packet
    packet.check_error()
  File "/home/ivan/PycharmProjects/transito/venv/lib/python3.6/site-packages/pymysql/protocol.py", line 220, in check_error
    err.raise_mysql_exception(self._data)
  File "/home/ivan/PycharmProjects/transito/venv/lib/python3.6/site-packages/pymysql/err.py", line 109, in raise_mysql_exception
    raise errorclass(errno, errval)
sqlalchemy.exc.OperationalError: (pymysql.err.OperationalError) (1044, "Access denied for user 'ivan'@'%' to database 'transito'")
(Background on this error at: http://sqlalche.me/e/e3q8)
2020-02-28 11:14 transito     ERROR    'list' object is not callable
Traceback (most recent call last):
  File "/home/ivan/PycharmProjects/transito/transito/routes/dta.py", line 19, in dta
    listaanexos = lista_anexos(session, dta_id)
TypeError: 'list' object is not callable
2020-02-28 11:14 transito     ERROR    'list' object is not callable
Traceback (most recent call last):
  File "/home/ivan/PycharmProjects/transito/transito/routes/dta.py", line 19, in dta
    listaanexos = lista_anexos(session, dta_id)
TypeError: 'list' object is not callable
2020-02-28 11:14 transito     ERROR    (pymysql.err.OperationalError) (1044, "Access denied for user 'ivan'@'%' to database 'transito'")
(Background on this error at: http://sqlalche.me/e/e3q8)
Traceback (most recent call last):
  File "/home/ivan/PycharmProjects/transito/venv/lib/python3.6/site-packages/sqlalchemy/engine/base.py", line 2276, in _wrap_pool_connect
    return fn()
  File "/home/ivan/PycharmProjects/transito/venv/lib/python3.6/site-packages/sqlalchemy/pool/base.py", line 363, in connect
    return _ConnectionFairy._checkout(self)
  File "/home/ivan/PycharmProjects/transito/venv/lib/python3.6/site-packages/sqlalchemy/pool/base.py", line 773, in _checkout
    fairy = _ConnectionRecord.checkout(pool)
  File "/home/ivan/PycharmProjects/transito/venv/lib/python3.6/site-packages/sqlalchemy/pool/base.py", line 492, in checkout
    rec = pool._do_get()
  File "/home/ivan/PycharmProjects/transito/venv/lib/python3.6/site-packages/sqlalchemy/pool/impl.py", line 139, in _do_get
    self._dec_overflow()
  File "/home/ivan/PycharmProjects/transito/venv/lib/python3.6/site-packages/sqlalchemy/util/langhelpers.py", line 68, in __exit__
    compat.reraise(exc_type, exc_value, exc_tb)
  File "/home/ivan/PycharmProjects/transito/venv/lib/python3.6/site-packages/sqlalchemy/util/compat.py", line 153, in reraise
    raise value
  File "/home/ivan/PycharmProjects/transito/venv/lib/python3.6/site-packages/sqlalchemy/pool/impl.py", line 136, in _do_get
    return self._create_connection()
  File "/home/ivan/PycharmProjects/transito/venv/lib/python3.6/site-packages/sqlalchemy/pool/base.py", line 308, in _create_connection
    return _ConnectionRecord(self)
  File "/home/ivan/PycharmProjects/transito/venv/lib/python3.6/site-packages/sqlalchemy/pool/base.py", line 437, in __init__
    self.__connect(first_connect_check=True)
  File "/home/ivan/PycharmProjects/transito/venv/lib/python3.6/site-packages/sqlalchemy/pool/base.py", line 652, in __connect
    connection = pool._invoke_creator(self)
  File "/home/ivan/PycharmProjects/transito/venv/lib/python3.6/site-packages/sqlalchemy/engine/strategies.py", line 114, in connect
    return dialect.connect(*cargs, **cparams)
  File "/home/ivan/PycharmProjects/transito/venv/lib/python3.6/site-packages/sqlalchemy/engine/default.py", line 489, in connect
    return self.dbapi.connect(*cargs, **cparams)
  File "/home/ivan/PycharmProjects/transito/venv/lib/python3.6/site-packages/pymysql/__init__.py", line 94, in Connect
    return Connection(*args, **kwargs)
  File "/home/ivan/PycharmProjects/transito/venv/lib/python3.6/site-packages/pymysql/connections.py", line 325, in __init__
    self.connect()
  File "/home/ivan/PycharmProjects/transito/venv/lib/python3.6/site-packages/pymysql/connections.py", line 599, in connect
    self._request_authentication()
  File "/home/ivan/PycharmProjects/transito/venv/lib/python3.6/site-packages/pymysql/connections.py", line 861, in _request_authentication
    auth_packet = self._read_packet()
  File "/home/ivan/PycharmProjects/transito/venv/lib/python3.6/site-packages/pymysql/connections.py", line 684, in _read_packet
    packet.check_error()
  File "/home/ivan/PycharmProjects/transito/venv/lib/python3.6/site-packages/pymysql/protocol.py", line 220, in check_error
    err.raise_mysql_exception(self._data)
  File "/home/ivan/PycharmProjects/transito/venv/lib/python3.6/site-packages/pymysql/err.py", line 109, in raise_mysql_exception
    raise errorclass(errno, errval)
pymysql.err.OperationalError: (1044, "Access denied for user 'ivan'@'%' to database 'transito'")

The above exception was the direct cause of the following exception:

Traceback (most recent call last):
  File "/home/ivan/PycharmProjects/transito/transito/routes/dta.py", line 19, in dta
    listaanexos = lista_anexos(session, dta_id)
  File "/home/ivan/PycharmProjects/transito/transito/models/dtamanager.py", line 15, in lista_anexos
    return session.query(Anexo).filter(Anexo.dta_id == dta_id).all()
  File "/home/ivan/PycharmProjects/transito/venv/lib/python3.6/site-packages/sqlalchemy/orm/query.py", line 3233, in all
    return list(self)
  File "/home/ivan/PycharmProjects/transito/venv/lib/python3.6/site-packages/sqlalchemy/orm/query.py", line 3389, in __iter__
    return self._execute_and_instances(context)
  File "/home/ivan/PycharmProjects/transito/venv/lib/python3.6/site-packages/sqlalchemy/orm/query.py", line 3411, in _execute_and_instances
    querycontext, self._connection_from_session, close_with_result=True
  File "/home/ivan/PycharmProjects/transito/venv/lib/python3.6/site-packages/sqlalchemy/orm/query.py", line 3426, in _get_bind_args
    mapper=self._bind_mapper(), clause=querycontext.statement, **kw
  File "/home/ivan/PycharmProjects/transito/venv/lib/python3.6/site-packages/sqlalchemy/orm/query.py", line 3404, in _connection_from_session
    conn = self.session.connection(**kw)
  File "/home/ivan/PycharmProjects/transito/venv/lib/python3.6/site-packages/sqlalchemy/orm/session.py", line 1133, in connection
    execution_options=execution_options,
  File "/home/ivan/PycharmProjects/transito/venv/lib/python3.6/site-packages/sqlalchemy/orm/session.py", line 1139, in _connection_for_bind
    engine, execution_options
  File "/home/ivan/PycharmProjects/transito/venv/lib/python3.6/site-packages/sqlalchemy/orm/session.py", line 432, in _connection_for_bind
    conn = bind._contextual_connect()
  File "/home/ivan/PycharmProjects/transito/venv/lib/python3.6/site-packages/sqlalchemy/engine/base.py", line 2242, in _contextual_connect
    self._wrap_pool_connect(self.pool.connect, None),
  File "/home/ivan/PycharmProjects/transito/venv/lib/python3.6/site-packages/sqlalchemy/engine/base.py", line 2280, in _wrap_pool_connect
    e, dialect, self
  File "/home/ivan/PycharmProjects/transito/venv/lib/python3.6/site-packages/sqlalchemy/engine/base.py", line 1547, in _handle_dbapi_exception_noconnection
    util.raise_from_cause(sqlalchemy_exception, exc_info)
  File "/home/ivan/PycharmProjects/transito/venv/lib/python3.6/site-packages/sqlalchemy/util/compat.py", line 398, in raise_from_cause
    reraise(type(exception), exception, tb=exc_tb, cause=cause)
  File "/home/ivan/PycharmProjects/transito/venv/lib/python3.6/site-packages/sqlalchemy/util/compat.py", line 152, in reraise
    raise value.with_traceback(tb)
  File "/home/ivan/PycharmProjects/transito/venv/lib/python3.6/site-packages/sqlalchemy/engine/base.py", line 2276, in _wrap_pool_connect
    return fn()
  File "/home/ivan/PycharmProjects/transito/venv/lib/python3.6/site-packages/sqlalchemy/pool/base.py", line 363, in connect
    return _ConnectionFairy._checkout(self)
  File "/home/ivan/PycharmProjects/transito/venv/lib/python3.6/site-packages/sqlalchemy/pool/base.py", line 773, in _checkout
    fairy = _ConnectionRecord.checkout(pool)
  File "/home/ivan/PycharmProjects/transito/venv/lib/python3.6/site-packages/sqlalchemy/pool/base.py", line 492, in checkout
    rec = pool._do_get()
  File "/home/ivan/PycharmProjects/transito/venv/lib/python3.6/site-packages/sqlalchemy/pool/impl.py", line 139, in _do_get
    self._dec_overflow()
  File "/home/ivan/PycharmProjects/transito/venv/lib/python3.6/site-packages/sqlalchemy/util/langhelpers.py", line 68, in __exit__
    compat.reraise(exc_type, exc_value, exc_tb)
  File "/home/ivan/PycharmProjects/transito/venv/lib/python3.6/site-packages/sqlalchemy/util/compat.py", line 153, in reraise
    raise value
  File "/home/ivan/PycharmProjects/transito/venv/lib/python3.6/site-packages/sqlalchemy/pool/impl.py", line 136, in _do_get
    return self._create_connection()
  File "/home/ivan/PycharmProjects/transito/venv/lib/python3.6/site-packages/sqlalchemy/pool/base.py", line 308, in _create_connection
    return _ConnectionRecord(self)
  File "/home/ivan/PycharmProjects/transito/venv/lib/python3.6/site-packages/sqlalchemy/pool/base.py", line 437, in __init__
    self.__connect(first_connect_check=True)
  File "/home/ivan/PycharmProjects/transito/venv/lib/python3.6/site-packages/sqlalchemy/pool/base.py", line 652, in __connect
    connection = pool._invoke_creator(self)
  File "/home/ivan/PycharmProjects/transito/venv/lib/python3.6/site-packages/sqlalchemy/engine/strategies.py", line 114, in connect
    return dialect.connect(*cargs, **cparams)
  File "/home/ivan/PycharmProjects/transito/venv/lib/python3.6/site-packages/sqlalchemy/engine/default.py", line 489, in connect
    return self.dbapi.connect(*cargs, **cparams)
  File "/home/ivan/PycharmProjects/transito/venv/lib/python3.6/site-packages/pymysql/__init__.py", line 94, in Connect
    return Connection(*args, **kwargs)
  File "/home/ivan/PycharmProjects/transito/venv/lib/python3.6/site-packages/pymysql/connections.py", line 325, in __init__
    self.connect()
  File "/home/ivan/PycharmProjects/transito/venv/lib/python3.6/site-packages/pymysql/connections.py", line 599, in connect
    self._request_authentication()
  File "/home/ivan/PycharmProjects/transito/venv/lib/python3.6/site-packages/pymysql/connections.py", line 861, in _request_authentication
    auth_packet = self._read_packet()
  File "/home/ivan/PycharmProjects/transito/venv/lib/python3.6/site-packages/pymysql/connections.py", line 684, in _read_packet
    packet.check_error()
  File "/home/ivan/PycharmProjects/transito/venv/lib/python3.6/site-packages/pymysql/protocol.py", line 220, in check_error
    err.raise_mysql_exception(self._data)
  File "/home/ivan/PycharmProjects/transito/venv/lib/python3.6/site-packages/pymysql/err.py", line 109, in raise_mysql_exception
    raise errorclass(errno, errval)
sqlalchemy.exc.OperationalError: (pymysql.err.OperationalError) (1044, "Access denied for user 'ivan'@'%' to database 'transito'")
(Background on this error at: http://sqlalche.me/e/e3q8)
2020-02-28 11:15 transito     ERROR    (pymysql.err.OperationalError) (1044, "Access denied for user 'ivan'@'%' to database 'transito'")
(Background on this error at: http://sqlalche.me/e/e3q8)
Traceback (most recent call last):
  File "/home/ivan/PycharmProjects/transito/venv/lib/python3.6/site-packages/sqlalchemy/engine/base.py", line 2276, in _wrap_pool_connect
    return fn()
  File "/home/ivan/PycharmProjects/transito/venv/lib/python3.6/site-packages/sqlalchemy/pool/base.py", line 363, in connect
    return _ConnectionFairy._checkout(self)
  File "/home/ivan/PycharmProjects/transito/venv/lib/python3.6/site-packages/sqlalchemy/pool/base.py", line 773, in _checkout
    fairy = _ConnectionRecord.checkout(pool)
  File "/home/ivan/PycharmProjects/transito/venv/lib/python3.6/site-packages/sqlalchemy/pool/base.py", line 492, in checkout
    rec = pool._do_get()
  File "/home/ivan/PycharmProjects/transito/venv/lib/python3.6/site-packages/sqlalchemy/pool/impl.py", line 139, in _do_get
    self._dec_overflow()
  File "/home/ivan/PycharmProjects/transito/venv/lib/python3.6/site-packages/sqlalchemy/util/langhelpers.py", line 68, in __exit__
    compat.reraise(exc_type, exc_value, exc_tb)
  File "/home/ivan/PycharmProjects/transito/venv/lib/python3.6/site-packages/sqlalchemy/util/compat.py", line 153, in reraise
    raise value
  File "/home/ivan/PycharmProjects/transito/venv/lib/python3.6/site-packages/sqlalchemy/pool/impl.py", line 136, in _do_get
    return self._create_connection()
  File "/home/ivan/PycharmProjects/transito/venv/lib/python3.6/site-packages/sqlalchemy/pool/base.py", line 308, in _create_connection
    return _ConnectionRecord(self)
  File "/home/ivan/PycharmProjects/transito/venv/lib/python3.6/site-packages/sqlalchemy/pool/base.py", line 437, in __init__
    self.__connect(first_connect_check=True)
  File "/home/ivan/PycharmProjects/transito/venv/lib/python3.6/site-packages/sqlalchemy/pool/base.py", line 652, in __connect
    connection = pool._invoke_creator(self)
  File "/home/ivan/PycharmProjects/transito/venv/lib/python3.6/site-packages/sqlalchemy/engine/strategies.py", line 114, in connect
    return dialect.connect(*cargs, **cparams)
  File "/home/ivan/PycharmProjects/transito/venv/lib/python3.6/site-packages/sqlalchemy/engine/default.py", line 489, in connect
    return self.dbapi.connect(*cargs, **cparams)
  File "/home/ivan/PycharmProjects/transito/venv/lib/python3.6/site-packages/pymysql/__init__.py", line 94, in Connect
    return Connection(*args, **kwargs)
  File "/home/ivan/PycharmProjects/transito/venv/lib/python3.6/site-packages/pymysql/connections.py", line 325, in __init__
    self.connect()
  File "/home/ivan/PycharmProjects/transito/venv/lib/python3.6/site-packages/pymysql/connections.py", line 599, in connect
    self._request_authentication()
  File "/home/ivan/PycharmProjects/transito/venv/lib/python3.6/site-packages/pymysql/connections.py", line 861, in _request_authentication
    auth_packet = self._read_packet()
  File "/home/ivan/PycharmProjects/transito/venv/lib/python3.6/site-packages/pymysql/connections.py", line 684, in _read_packet
    packet.check_error()
  File "/home/ivan/PycharmProjects/transito/venv/lib/python3.6/site-packages/pymysql/protocol.py", line 220, in check_error
    err.raise_mysql_exception(self._data)
  File "/home/ivan/PycharmProjects/transito/venv/lib/python3.6/site-packages/pymysql/err.py", line 109, in raise_mysql_exception
    raise errorclass(errno, errval)
pymysql.err.OperationalError: (1044, "Access denied for user 'ivan'@'%' to database 'transito'")

The above exception was the direct cause of the following exception:

Traceback (most recent call last):
  File "/home/ivan/PycharmProjects/transito/transito/routes/dta.py", line 19, in dta
    listaanexos = lista_anexos(session, dta_id)
  File "/home/ivan/PycharmProjects/transito/transito/models/dtamanager.py", line 15, in lista_anexos
    return session.query(Anexo).filter(Anexo.dta_id == dta_id).all()
  File "/home/ivan/PycharmProjects/transito/venv/lib/python3.6/site-packages/sqlalchemy/orm/query.py", line 3233, in all
    return list(self)
  File "/home/ivan/PycharmProjects/transito/venv/lib/python3.6/site-packages/sqlalchemy/orm/query.py", line 3389, in __iter__
    return self._execute_and_instances(context)
  File "/home/ivan/PycharmProjects/transito/venv/lib/python3.6/site-packages/sqlalchemy/orm/query.py", line 3411, in _execute_and_instances
    querycontext, self._connection_from_session, close_with_result=True
  File "/home/ivan/PycharmProjects/transito/venv/lib/python3.6/site-packages/sqlalchemy/orm/query.py", line 3426, in _get_bind_args
    mapper=self._bind_mapper(), clause=querycontext.statement, **kw
  File "/home/ivan/PycharmProjects/transito/venv/lib/python3.6/site-packages/sqlalchemy/orm/query.py", line 3404, in _connection_from_session
    conn = self.session.connection(**kw)
  File "/home/ivan/PycharmProjects/transito/venv/lib/python3.6/site-packages/sqlalchemy/orm/session.py", line 1133, in connection
    execution_options=execution_options,
  File "/home/ivan/PycharmProjects/transito/venv/lib/python3.6/site-packages/sqlalchemy/orm/session.py", line 1139, in _connection_for_bind
    engine, execution_options
  File "/home/ivan/PycharmProjects/transito/venv/lib/python3.6/site-packages/sqlalchemy/orm/session.py", line 432, in _connection_for_bind
    conn = bind._contextual_connect()
  File "/home/ivan/PycharmProjects/transito/venv/lib/python3.6/site-packages/sqlalchemy/engine/base.py", line 2242, in _contextual_connect
    self._wrap_pool_connect(self.pool.connect, None),
  File "/home/ivan/PycharmProjects/transito/venv/lib/python3.6/site-packages/sqlalchemy/engine/base.py", line 2280, in _wrap_pool_connect
    e, dialect, self
  File "/home/ivan/PycharmProjects/transito/venv/lib/python3.6/site-packages/sqlalchemy/engine/base.py", line 1547, in _handle_dbapi_exception_noconnection
    util.raise_from_cause(sqlalchemy_exception, exc_info)
  File "/home/ivan/PycharmProjects/transito/venv/lib/python3.6/site-packages/sqlalchemy/util/compat.py", line 398, in raise_from_cause
    reraise(type(exception), exception, tb=exc_tb, cause=cause)
  File "/home/ivan/PycharmProjects/transito/venv/lib/python3.6/site-packages/sqlalchemy/util/compat.py", line 152, in reraise
    raise value.with_traceback(tb)
  File "/home/ivan/PycharmProjects/transito/venv/lib/python3.6/site-packages/sqlalchemy/engine/base.py", line 2276, in _wrap_pool_connect
    return fn()
  File "/home/ivan/PycharmProjects/transito/venv/lib/python3.6/site-packages/sqlalchemy/pool/base.py", line 363, in connect
    return _ConnectionFairy._checkout(self)
  File "/home/ivan/PycharmProjects/transito/venv/lib/python3.6/site-packages/sqlalchemy/pool/base.py", line 773, in _checkout
    fairy = _ConnectionRecord.checkout(pool)
  File "/home/ivan/PycharmProjects/transito/venv/lib/python3.6/site-packages/sqlalchemy/pool/base.py", line 492, in checkout
    rec = pool._do_get()
  File "/home/ivan/PycharmProjects/transito/venv/lib/python3.6/site-packages/sqlalchemy/pool/impl.py", line 139, in _do_get
    self._dec_overflow()
  File "/home/ivan/PycharmProjects/transito/venv/lib/python3.6/site-packages/sqlalchemy/util/langhelpers.py", line 68, in __exit__
    compat.reraise(exc_type, exc_value, exc_tb)
  File "/home/ivan/PycharmProjects/transito/venv/lib/python3.6/site-packages/sqlalchemy/util/compat.py", line 153, in reraise
    raise value
  File "/home/ivan/PycharmProjects/transito/venv/lib/python3.6/site-packages/sqlalchemy/pool/impl.py", line 136, in _do_get
    return self._create_connection()
  File "/home/ivan/PycharmProjects/transito/venv/lib/python3.6/site-packages/sqlalchemy/pool/base.py", line 308, in _create_connection
    return _ConnectionRecord(self)
  File "/home/ivan/PycharmProjects/transito/venv/lib/python3.6/site-packages/sqlalchemy/pool/base.py", line 437, in __init__
    self.__connect(first_connect_check=True)
  File "/home/ivan/PycharmProjects/transito/venv/lib/python3.6/site-packages/sqlalchemy/pool/base.py", line 652, in __connect
    connection = pool._invoke_creator(self)
  File "/home/ivan/PycharmProjects/transito/venv/lib/python3.6/site-packages/sqlalchemy/engine/strategies.py", line 114, in connect
    return dialect.connect(*cargs, **cparams)
  File "/home/ivan/PycharmProjects/transito/venv/lib/python3.6/site-packages/sqlalchemy/engine/default.py", line 489, in connect
    return self.dbapi.connect(*cargs, **cparams)
  File "/home/ivan/PycharmProjects/transito/venv/lib/python3.6/site-packages/pymysql/__init__.py", line 94, in Connect
    return Connection(*args, **kwargs)
  File "/home/ivan/PycharmProjects/transito/venv/lib/python3.6/site-packages/pymysql/connections.py", line 325, in __init__
    self.connect()
  File "/home/ivan/PycharmProjects/transito/venv/lib/python3.6/site-packages/pymysql/connections.py", line 599, in connect
    self._request_authentication()
  File "/home/ivan/PycharmProjects/transito/venv/lib/python3.6/site-packages/pymysql/connections.py", line 861, in _request_authentication
    auth_packet = self._read_packet()
  File "/home/ivan/PycharmProjects/transito/venv/lib/python3.6/site-packages/pymysql/connections.py", line 684, in _read_packet
    packet.check_error()
  File "/home/ivan/PycharmProjects/transito/venv/lib/python3.6/site-packages/pymysql/protocol.py", line 220, in check_error
    err.raise_mysql_exception(self._data)
  File "/home/ivan/PycharmProjects/transito/venv/lib/python3.6/site-packages/pymysql/err.py", line 109, in raise_mysql_exception
    raise errorclass(errno, errval)
sqlalchemy.exc.OperationalError: (pymysql.err.OperationalError) (1044, "Access denied for user 'ivan'@'%' to database 'transito'")
(Background on this error at: http://sqlalche.me/e/e3q8)
2020-02-28 11:15 transito     ERROR    (pymysql.err.OperationalError) (1044, "Access denied for user 'ivan'@'%' to database 'transito'")
(Background on this error at: http://sqlalche.me/e/e3q8)
Traceback (most recent call last):
  File "/home/ivan/PycharmProjects/transito/venv/lib/python3.6/site-packages/sqlalchemy/engine/base.py", line 2276, in _wrap_pool_connect
    return fn()
  File "/home/ivan/PycharmProjects/transito/venv/lib/python3.6/site-packages/sqlalchemy/pool/base.py", line 363, in connect
    return _ConnectionFairy._checkout(self)
  File "/home/ivan/PycharmProjects/transito/venv/lib/python3.6/site-packages/sqlalchemy/pool/base.py", line 773, in _checkout
    fairy = _ConnectionRecord.checkout(pool)
  File "/home/ivan/PycharmProjects/transito/venv/lib/python3.6/site-packages/sqlalchemy/pool/base.py", line 492, in checkout
    rec = pool._do_get()
  File "/home/ivan/PycharmProjects/transito/venv/lib/python3.6/site-packages/sqlalchemy/pool/impl.py", line 139, in _do_get
    self._dec_overflow()
  File "/home/ivan/PycharmProjects/transito/venv/lib/python3.6/site-packages/sqlalchemy/util/langhelpers.py", line 68, in __exit__
    compat.reraise(exc_type, exc_value, exc_tb)
  File "/home/ivan/PycharmProjects/transito/venv/lib/python3.6/site-packages/sqlalchemy/util/compat.py", line 153, in reraise
    raise value
  File "/home/ivan/PycharmProjects/transito/venv/lib/python3.6/site-packages/sqlalchemy/pool/impl.py", line 136, in _do_get
    return self._create_connection()
  File "/home/ivan/PycharmProjects/transito/venv/lib/python3.6/site-packages/sqlalchemy/pool/base.py", line 308, in _create_connection
    return _ConnectionRecord(self)
  File "/home/ivan/PycharmProjects/transito/venv/lib/python3.6/site-packages/sqlalchemy/pool/base.py", line 437, in __init__
    self.__connect(first_connect_check=True)
  File "/home/ivan/PycharmProjects/transito/venv/lib/python3.6/site-packages/sqlalchemy/pool/base.py", line 652, in __connect
    connection = pool._invoke_creator(self)
  File "/home/ivan/PycharmProjects/transito/venv/lib/python3.6/site-packages/sqlalchemy/engine/strategies.py", line 114, in connect
    return dialect.connect(*cargs, **cparams)
  File "/home/ivan/PycharmProjects/transito/venv/lib/python3.6/site-packages/sqlalchemy/engine/default.py", line 489, in connect
    return self.dbapi.connect(*cargs, **cparams)
  File "/home/ivan/PycharmProjects/transito/venv/lib/python3.6/site-packages/pymysql/__init__.py", line 94, in Connect
    return Connection(*args, **kwargs)
  File "/home/ivan/PycharmProjects/transito/venv/lib/python3.6/site-packages/pymysql/connections.py", line 325, in __init__
    self.connect()
  File "/home/ivan/PycharmProjects/transito/venv/lib/python3.6/site-packages/pymysql/connections.py", line 599, in connect
    self._request_authentication()
  File "/home/ivan/PycharmProjects/transito/venv/lib/python3.6/site-packages/pymysql/connections.py", line 861, in _request_authentication
    auth_packet = self._read_packet()
  File "/home/ivan/PycharmProjects/transito/venv/lib/python3.6/site-packages/pymysql/connections.py", line 684, in _read_packet
    packet.check_error()
  File "/home/ivan/PycharmProjects/transito/venv/lib/python3.6/site-packages/pymysql/protocol.py", line 220, in check_error
    err.raise_mysql_exception(self._data)
  File "/home/ivan/PycharmProjects/transito/venv/lib/python3.6/site-packages/pymysql/err.py", line 109, in raise_mysql_exception
    raise errorclass(errno, errval)
pymysql.err.OperationalError: (1044, "Access denied for user 'ivan'@'%' to database 'transito'")

The above exception was the direct cause of the following exception:

Traceback (most recent call last):
  File "/home/ivan/PycharmProjects/transito/transito/routes/dta.py", line 19, in dta
    listaanexos = lista_anexos(session, dta_id)
  File "/home/ivan/PycharmProjects/transito/transito/models/dtamanager.py", line 15, in lista_anexos
    return session.query(Anexo).filter(Anexo.dta_id == dta_id).all()
  File "/home/ivan/PycharmProjects/transito/venv/lib/python3.6/site-packages/sqlalchemy/orm/query.py", line 3233, in all
    return list(self)
  File "/home/ivan/PycharmProjects/transito/venv/lib/python3.6/site-packages/sqlalchemy/orm/query.py", line 3389, in __iter__
    return self._execute_and_instances(context)
  File "/home/ivan/PycharmProjects/transito/venv/lib/python3.6/site-packages/sqlalchemy/orm/query.py", line 3411, in _execute_and_instances
    querycontext, self._connection_from_session, close_with_result=True
  File "/home/ivan/PycharmProjects/transito/venv/lib/python3.6/site-packages/sqlalchemy/orm/query.py", line 3426, in _get_bind_args
    mapper=self._bind_mapper(), clause=querycontext.statement, **kw
  File "/home/ivan/PycharmProjects/transito/venv/lib/python3.6/site-packages/sqlalchemy/orm/query.py", line 3404, in _connection_from_session
    conn = self.session.connection(**kw)
  File "/home/ivan/PycharmProjects/transito/venv/lib/python3.6/site-packages/sqlalchemy/orm/session.py", line 1133, in connection
    execution_options=execution_options,
  File "/home/ivan/PycharmProjects/transito/venv/lib/python3.6/site-packages/sqlalchemy/orm/session.py", line 1139, in _connection_for_bind
    engine, execution_options
  File "/home/ivan/PycharmProjects/transito/venv/lib/python3.6/site-packages/sqlalchemy/orm/session.py", line 432, in _connection_for_bind
    conn = bind._contextual_connect()
  File "/home/ivan/PycharmProjects/transito/venv/lib/python3.6/site-packages/sqlalchemy/engine/base.py", line 2242, in _contextual_connect
    self._wrap_pool_connect(self.pool.connect, None),
  File "/home/ivan/PycharmProjects/transito/venv/lib/python3.6/site-packages/sqlalchemy/engine/base.py", line 2280, in _wrap_pool_connect
    e, dialect, self
  File "/home/ivan/PycharmProjects/transito/venv/lib/python3.6/site-packages/sqlalchemy/engine/base.py", line 1547, in _handle_dbapi_exception_noconnection
    util.raise_from_cause(sqlalchemy_exception, exc_info)
  File "/home/ivan/PycharmProjects/transito/venv/lib/python3.6/site-packages/sqlalchemy/util/compat.py", line 398, in raise_from_cause
    reraise(type(exception), exception, tb=exc_tb, cause=cause)
  File "/home/ivan/PycharmProjects/transito/venv/lib/python3.6/site-packages/sqlalchemy/util/compat.py", line 152, in reraise
    raise value.with_traceback(tb)
  File "/home/ivan/PycharmProjects/transito/venv/lib/python3.6/site-packages/sqlalchemy/engine/base.py", line 2276, in _wrap_pool_connect
    return fn()
  File "/home/ivan/PycharmProjects/transito/venv/lib/python3.6/site-packages/sqlalchemy/pool/base.py", line 363, in connect
    return _ConnectionFairy._checkout(self)
  File "/home/ivan/PycharmProjects/transito/venv/lib/python3.6/site-packages/sqlalchemy/pool/base.py", line 773, in _checkout
    fairy = _ConnectionRecord.checkout(pool)
  File "/home/ivan/PycharmProjects/transito/venv/lib/python3.6/site-packages/sqlalchemy/pool/base.py", line 492, in checkout
    rec = pool._do_get()
  File "/home/ivan/PycharmProjects/transito/venv/lib/python3.6/site-packages/sqlalchemy/pool/impl.py", line 139, in _do_get
    self._dec_overflow()
  File "/home/ivan/PycharmProjects/transito/venv/lib/python3.6/site-packages/sqlalchemy/util/langhelpers.py", line 68, in __exit__
    compat.reraise(exc_type, exc_value, exc_tb)
  File "/home/ivan/PycharmProjects/transito/venv/lib/python3.6/site-packages/sqlalchemy/util/compat.py", line 153, in reraise
    raise value
  File "/home/ivan/PycharmProjects/transito/venv/lib/python3.6/site-packages/sqlalchemy/pool/impl.py", line 136, in _do_get
    return self._create_connection()
  File "/home/ivan/PycharmProjects/transito/venv/lib/python3.6/site-packages/sqlalchemy/pool/base.py", line 308, in _create_connection
    return _ConnectionRecord(self)
  File "/home/ivan/PycharmProjects/transito/venv/lib/python3.6/site-packages/sqlalchemy/pool/base.py", line 437, in __init__
    self.__connect(first_connect_check=True)
  File "/home/ivan/PycharmProjects/transito/venv/lib/python3.6/site-packages/sqlalchemy/pool/base.py", line 652, in __connect
    connection = pool._invoke_creator(self)
  File "/home/ivan/PycharmProjects/transito/venv/lib/python3.6/site-packages/sqlalchemy/engine/strategies.py", line 114, in connect
    return dialect.connect(*cargs, **cparams)
  File "/home/ivan/PycharmProjects/transito/venv/lib/python3.6/site-packages/sqlalchemy/engine/default.py", line 489, in connect
    return self.dbapi.connect(*cargs, **cparams)
  File "/home/ivan/PycharmProjects/transito/venv/lib/python3.6/site-packages/pymysql/__init__.py", line 94, in Connect
    return Connection(*args, **kwargs)
  File "/home/ivan/PycharmProjects/transito/venv/lib/python3.6/site-packages/pymysql/connections.py", line 325, in __init__
    self.connect()
  File "/home/ivan/PycharmProjects/transito/venv/lib/python3.6/site-packages/pymysql/connections.py", line 599, in connect
    self._request_authentication()
  File "/home/ivan/PycharmProjects/transito/venv/lib/python3.6/site-packages/pymysql/connections.py", line 861, in _request_authentication
    auth_packet = self._read_packet()
  File "/home/ivan/PycharmProjects/transito/venv/lib/python3.6/site-packages/pymysql/connections.py", line 684, in _read_packet
    packet.check_error()
  File "/home/ivan/PycharmProjects/transito/venv/lib/python3.6/site-packages/pymysql/protocol.py", line 220, in check_error
    err.raise_mysql_exception(self._data)
  File "/home/ivan/PycharmProjects/transito/venv/lib/python3.6/site-packages/pymysql/err.py", line 109, in raise_mysql_exception
    raise errorclass(errno, errval)
sqlalchemy.exc.OperationalError: (pymysql.err.OperationalError) (1044, "Access denied for user 'ivan'@'%' to database 'transito'")
(Background on this error at: http://sqlalche.me/e/e3q8)
2020-02-28 11:23 transito     ERROR    (pymysql.err.OperationalError) (1044, "Access denied for user 'ivan'@'%' to database 'transito'")
(Background on this error at: http://sqlalche.me/e/e3q8)
Traceback (most recent call last):
  File "/home/ivan/PycharmProjects/transito/venv/lib/python3.6/site-packages/sqlalchemy/engine/base.py", line 2276, in _wrap_pool_connect
    return fn()
  File "/home/ivan/PycharmProjects/transito/venv/lib/python3.6/site-packages/sqlalchemy/pool/base.py", line 363, in connect
    return _ConnectionFairy._checkout(self)
  File "/home/ivan/PycharmProjects/transito/venv/lib/python3.6/site-packages/sqlalchemy/pool/base.py", line 773, in _checkout
    fairy = _ConnectionRecord.checkout(pool)
  File "/home/ivan/PycharmProjects/transito/venv/lib/python3.6/site-packages/sqlalchemy/pool/base.py", line 492, in checkout
    rec = pool._do_get()
  File "/home/ivan/PycharmProjects/transito/venv/lib/python3.6/site-packages/sqlalchemy/pool/impl.py", line 139, in _do_get
    self._dec_overflow()
  File "/home/ivan/PycharmProjects/transito/venv/lib/python3.6/site-packages/sqlalchemy/util/langhelpers.py", line 68, in __exit__
    compat.reraise(exc_type, exc_value, exc_tb)
  File "/home/ivan/PycharmProjects/transito/venv/lib/python3.6/site-packages/sqlalchemy/util/compat.py", line 153, in reraise
    raise value
  File "/home/ivan/PycharmProjects/transito/venv/lib/python3.6/site-packages/sqlalchemy/pool/impl.py", line 136, in _do_get
    return self._create_connection()
  File "/home/ivan/PycharmProjects/transito/venv/lib/python3.6/site-packages/sqlalchemy/pool/base.py", line 308, in _create_connection
    return _ConnectionRecord(self)
  File "/home/ivan/PycharmProjects/transito/venv/lib/python3.6/site-packages/sqlalchemy/pool/base.py", line 437, in __init__
    self.__connect(first_connect_check=True)
  File "/home/ivan/PycharmProjects/transito/venv/lib/python3.6/site-packages/sqlalchemy/pool/base.py", line 652, in __connect
    connection = pool._invoke_creator(self)
  File "/home/ivan/PycharmProjects/transito/venv/lib/python3.6/site-packages/sqlalchemy/engine/strategies.py", line 114, in connect
    return dialect.connect(*cargs, **cparams)
  File "/home/ivan/PycharmProjects/transito/venv/lib/python3.6/site-packages/sqlalchemy/engine/default.py", line 489, in connect
    return self.dbapi.connect(*cargs, **cparams)
  File "/home/ivan/PycharmProjects/transito/venv/lib/python3.6/site-packages/pymysql/__init__.py", line 94, in Connect
    return Connection(*args, **kwargs)
  File "/home/ivan/PycharmProjects/transito/venv/lib/python3.6/site-packages/pymysql/connections.py", line 325, in __init__
    self.connect()
  File "/home/ivan/PycharmProjects/transito/venv/lib/python3.6/site-packages/pymysql/connections.py", line 599, in connect
    self._request_authentication()
  File "/home/ivan/PycharmProjects/transito/venv/lib/python3.6/site-packages/pymysql/connections.py", line 861, in _request_authentication
    auth_packet = self._read_packet()
  File "/home/ivan/PycharmProjects/transito/venv/lib/python3.6/site-packages/pymysql/connections.py", line 684, in _read_packet
    packet.check_error()
  File "/home/ivan/PycharmProjects/transito/venv/lib/python3.6/site-packages/pymysql/protocol.py", line 220, in check_error
    err.raise_mysql_exception(self._data)
  File "/home/ivan/PycharmProjects/transito/venv/lib/python3.6/site-packages/pymysql/err.py", line 109, in raise_mysql_exception
    raise errorclass(errno, errval)
pymysql.err.OperationalError: (1044, "Access denied for user 'ivan'@'%' to database 'transito'")

The above exception was the direct cause of the following exception:

Traceback (most recent call last):
  File "/home/ivan/PycharmProjects/transito/transito/routes/dta.py", line 19, in dta
    listaanexos = lista_anexos(session, dta_id)
  File "/home/ivan/PycharmProjects/transito/transito/models/dtamanager.py", line 15, in lista_anexos
    return session.query(Anexo).filter(Anexo.dta_id == dta_id).all()
  File "/home/ivan/PycharmProjects/transito/venv/lib/python3.6/site-packages/sqlalchemy/orm/query.py", line 3233, in all
    return list(self)
  File "/home/ivan/PycharmProjects/transito/venv/lib/python3.6/site-packages/sqlalchemy/orm/query.py", line 3389, in __iter__
    return self._execute_and_instances(context)
  File "/home/ivan/PycharmProjects/transito/venv/lib/python3.6/site-packages/sqlalchemy/orm/query.py", line 3411, in _execute_and_instances
    querycontext, self._connection_from_session, close_with_result=True
  File "/home/ivan/PycharmProjects/transito/venv/lib/python3.6/site-packages/sqlalchemy/orm/query.py", line 3426, in _get_bind_args
    mapper=self._bind_mapper(), clause=querycontext.statement, **kw
  File "/home/ivan/PycharmProjects/transito/venv/lib/python3.6/site-packages/sqlalchemy/orm/query.py", line 3404, in _connection_from_session
    conn = self.session.connection(**kw)
  File "/home/ivan/PycharmProjects/transito/venv/lib/python3.6/site-packages/sqlalchemy/orm/session.py", line 1133, in connection
    execution_options=execution_options,
  File "/home/ivan/PycharmProjects/transito/venv/lib/python3.6/site-packages/sqlalchemy/orm/session.py", line 1139, in _connection_for_bind
    engine, execution_options
  File "/home/ivan/PycharmProjects/transito/venv/lib/python3.6/site-packages/sqlalchemy/orm/session.py", line 432, in _connection_for_bind
    conn = bind._contextual_connect()
  File "/home/ivan/PycharmProjects/transito/venv/lib/python3.6/site-packages/sqlalchemy/engine/base.py", line 2242, in _contextual_connect
    self._wrap_pool_connect(self.pool.connect, None),
  File "/home/ivan/PycharmProjects/transito/venv/lib/python3.6/site-packages/sqlalchemy/engine/base.py", line 2280, in _wrap_pool_connect
    e, dialect, self
  File "/home/ivan/PycharmProjects/transito/venv/lib/python3.6/site-packages/sqlalchemy/engine/base.py", line 1547, in _handle_dbapi_exception_noconnection
    util.raise_from_cause(sqlalchemy_exception, exc_info)
  File "/home/ivan/PycharmProjects/transito/venv/lib/python3.6/site-packages/sqlalchemy/util/compat.py", line 398, in raise_from_cause
    reraise(type(exception), exception, tb=exc_tb, cause=cause)
  File "/home/ivan/PycharmProjects/transito/venv/lib/python3.6/site-packages/sqlalchemy/util/compat.py", line 152, in reraise
    raise value.with_traceback(tb)
  File "/home/ivan/PycharmProjects/transito/venv/lib/python3.6/site-packages/sqlalchemy/engine/base.py", line 2276, in _wrap_pool_connect
    return fn()
  File "/home/ivan/PycharmProjects/transito/venv/lib/python3.6/site-packages/sqlalchemy/pool/base.py", line 363, in connect
    return _ConnectionFairy._checkout(self)
  File "/home/ivan/PycharmProjects/transito/venv/lib/python3.6/site-packages/sqlalchemy/pool/base.py", line 773, in _checkout
    fairy = _ConnectionRecord.checkout(pool)
  File "/home/ivan/PycharmProjects/transito/venv/lib/python3.6/site-packages/sqlalchemy/pool/base.py", line 492, in checkout
    rec = pool._do_get()
  File "/home/ivan/PycharmProjects/transito/venv/lib/python3.6/site-packages/sqlalchemy/pool/impl.py", line 139, in _do_get
    self._dec_overflow()
  File "/home/ivan/PycharmProjects/transito/venv/lib/python3.6/site-packages/sqlalchemy/util/langhelpers.py", line 68, in __exit__
    compat.reraise(exc_type, exc_value, exc_tb)
  File "/home/ivan/PycharmProjects/transito/venv/lib/python3.6/site-packages/sqlalchemy/util/compat.py", line 153, in reraise
    raise value
  File "/home/ivan/PycharmProjects/transito/venv/lib/python3.6/site-packages/sqlalchemy/pool/impl.py", line 136, in _do_get
    return self._create_connection()
  File "/home/ivan/PycharmProjects/transito/venv/lib/python3.6/site-packages/sqlalchemy/pool/base.py", line 308, in _create_connection
    return _ConnectionRecord(self)
  File "/home/ivan/PycharmProjects/transito/venv/lib/python3.6/site-packages/sqlalchemy/pool/base.py", line 437, in __init__
    self.__connect(first_connect_check=True)
  File "/home/ivan/PycharmProjects/transito/venv/lib/python3.6/site-packages/sqlalchemy/pool/base.py", line 652, in __connect
    connection = pool._invoke_creator(self)
  File "/home/ivan/PycharmProjects/transito/venv/lib/python3.6/site-packages/sqlalchemy/engine/strategies.py", line 114, in connect
    return dialect.connect(*cargs, **cparams)
  File "/home/ivan/PycharmProjects/transito/venv/lib/python3.6/site-packages/sqlalchemy/engine/default.py", line 489, in connect
    return self.dbapi.connect(*cargs, **cparams)
  File "/home/ivan/PycharmProjects/transito/venv/lib/python3.6/site-packages/pymysql/__init__.py", line 94, in Connect
    return Connection(*args, **kwargs)
  File "/home/ivan/PycharmProjects/transito/venv/lib/python3.6/site-packages/pymysql/connections.py", line 325, in __init__
    self.connect()
  File "/home/ivan/PycharmProjects/transito/venv/lib/python3.6/site-packages/pymysql/connections.py", line 599, in connect
    self._request_authentication()
  File "/home/ivan/PycharmProjects/transito/venv/lib/python3.6/site-packages/pymysql/connections.py", line 861, in _request_authentication
    auth_packet = self._read_packet()
  File "/home/ivan/PycharmProjects/transito/venv/lib/python3.6/site-packages/pymysql/connections.py", line 684, in _read_packet
    packet.check_error()
  File "/home/ivan/PycharmProjects/transito/venv/lib/python3.6/site-packages/pymysql/protocol.py", line 220, in check_error
    err.raise_mysql_exception(self._data)
  File "/home/ivan/PycharmProjects/transito/venv/lib/python3.6/site-packages/pymysql/err.py", line 109, in raise_mysql_exception
    raise errorclass(errno, errval)
sqlalchemy.exc.OperationalError: (pymysql.err.OperationalError) (1044, "Access denied for user 'ivan'@'%' to database 'transito'")
(Background on this error at: http://sqlalche.me/e/e3q8)
2020-02-28 11:23 transito     ERROR    (pymysql.err.OperationalError) (1044, "Access denied for user 'ivan'@'%' to database 'transito'")
(Background on this error at: http://sqlalche.me/e/e3q8)
Traceback (most recent call last):
  File "/home/ivan/PycharmProjects/transito/venv/lib/python3.6/site-packages/sqlalchemy/engine/base.py", line 2276, in _wrap_pool_connect
    return fn()
  File "/home/ivan/PycharmProjects/transito/venv/lib/python3.6/site-packages/sqlalchemy/pool/base.py", line 363, in connect
    return _ConnectionFairy._checkout(self)
  File "/home/ivan/PycharmProjects/transito/venv/lib/python3.6/site-packages/sqlalchemy/pool/base.py", line 773, in _checkout
    fairy = _ConnectionRecord.checkout(pool)
  File "/home/ivan/PycharmProjects/transito/venv/lib/python3.6/site-packages/sqlalchemy/pool/base.py", line 492, in checkout
    rec = pool._do_get()
  File "/home/ivan/PycharmProjects/transito/venv/lib/python3.6/site-packages/sqlalchemy/pool/impl.py", line 139, in _do_get
    self._dec_overflow()
  File "/home/ivan/PycharmProjects/transito/venv/lib/python3.6/site-packages/sqlalchemy/util/langhelpers.py", line 68, in __exit__
    compat.reraise(exc_type, exc_value, exc_tb)
  File "/home/ivan/PycharmProjects/transito/venv/lib/python3.6/site-packages/sqlalchemy/util/compat.py", line 153, in reraise
    raise value
  File "/home/ivan/PycharmProjects/transito/venv/lib/python3.6/site-packages/sqlalchemy/pool/impl.py", line 136, in _do_get
    return self._create_connection()
  File "/home/ivan/PycharmProjects/transito/venv/lib/python3.6/site-packages/sqlalchemy/pool/base.py", line 308, in _create_connection
    return _ConnectionRecord(self)
  File "/home/ivan/PycharmProjects/transito/venv/lib/python3.6/site-packages/sqlalchemy/pool/base.py", line 437, in __init__
    self.__connect(first_connect_check=True)
  File "/home/ivan/PycharmProjects/transito/venv/lib/python3.6/site-packages/sqlalchemy/pool/base.py", line 652, in __connect
    connection = pool._invoke_creator(self)
  File "/home/ivan/PycharmProjects/transito/venv/lib/python3.6/site-packages/sqlalchemy/engine/strategies.py", line 114, in connect
    return dialect.connect(*cargs, **cparams)
  File "/home/ivan/PycharmProjects/transito/venv/lib/python3.6/site-packages/sqlalchemy/engine/default.py", line 489, in connect
    return self.dbapi.connect(*cargs, **cparams)
  File "/home/ivan/PycharmProjects/transito/venv/lib/python3.6/site-packages/pymysql/__init__.py", line 94, in Connect
    return Connection(*args, **kwargs)
  File "/home/ivan/PycharmProjects/transito/venv/lib/python3.6/site-packages/pymysql/connections.py", line 325, in __init__
    self.connect()
  File "/home/ivan/PycharmProjects/transito/venv/lib/python3.6/site-packages/pymysql/connections.py", line 599, in connect
    self._request_authentication()
  File "/home/ivan/PycharmProjects/transito/venv/lib/python3.6/site-packages/pymysql/connections.py", line 861, in _request_authentication
    auth_packet = self._read_packet()
  File "/home/ivan/PycharmProjects/transito/venv/lib/python3.6/site-packages/pymysql/connections.py", line 684, in _read_packet
    packet.check_error()
  File "/home/ivan/PycharmProjects/transito/venv/lib/python3.6/site-packages/pymysql/protocol.py", line 220, in check_error
    err.raise_mysql_exception(self._data)
  File "/home/ivan/PycharmProjects/transito/venv/lib/python3.6/site-packages/pymysql/err.py", line 109, in raise_mysql_exception
    raise errorclass(errno, errval)
pymysql.err.OperationalError: (1044, "Access denied for user 'ivan'@'%' to database 'transito'")

The above exception was the direct cause of the following exception:

Traceback (most recent call last):
  File "/home/ivan/PycharmProjects/transito/transito/routes/dta.py", line 19, in dta
    listaanexos = lista_anexos(session, dta_id)
  File "/home/ivan/PycharmProjects/transito/transito/models/dtamanager.py", line 15, in lista_anexos
    return session.query(Anexo).filter(Anexo.dta_id == dta_id).all()
  File "/home/ivan/PycharmProjects/transito/venv/lib/python3.6/site-packages/sqlalchemy/orm/query.py", line 3233, in all
    return list(self)
  File "/home/ivan/PycharmProjects/transito/venv/lib/python3.6/site-packages/sqlalchemy/orm/query.py", line 3389, in __iter__
    return self._execute_and_instances(context)
  File "/home/ivan/PycharmProjects/transito/venv/lib/python3.6/site-packages/sqlalchemy/orm/query.py", line 3411, in _execute_and_instances
    querycontext, self._connection_from_session, close_with_result=True
  File "/home/ivan/PycharmProjects/transito/venv/lib/python3.6/site-packages/sqlalchemy/orm/query.py", line 3426, in _get_bind_args
    mapper=self._bind_mapper(), clause=querycontext.statement, **kw
  File "/home/ivan/PycharmProjects/transito/venv/lib/python3.6/site-packages/sqlalchemy/orm/query.py", line 3404, in _connection_from_session
    conn = self.session.connection(**kw)
  File "/home/ivan/PycharmProjects/transito/venv/lib/python3.6/site-packages/sqlalchemy/orm/session.py", line 1133, in connection
    execution_options=execution_options,
  File "/home/ivan/PycharmProjects/transito/venv/lib/python3.6/site-packages/sqlalchemy/orm/session.py", line 1139, in _connection_for_bind
    engine, execution_options
  File "/home/ivan/PycharmProjects/transito/venv/lib/python3.6/site-packages/sqlalchemy/orm/session.py", line 432, in _connection_for_bind
    conn = bind._contextual_connect()
  File "/home/ivan/PycharmProjects/transito/venv/lib/python3.6/site-packages/sqlalchemy/engine/base.py", line 2242, in _contextual_connect
    self._wrap_pool_connect(self.pool.connect, None),
  File "/home/ivan/PycharmProjects/transito/venv/lib/python3.6/site-packages/sqlalchemy/engine/base.py", line 2280, in _wrap_pool_connect
    e, dialect, self
  File "/home/ivan/PycharmProjects/transito/venv/lib/python3.6/site-packages/sqlalchemy/engine/base.py", line 1547, in _handle_dbapi_exception_noconnection
    util.raise_from_cause(sqlalchemy_exception, exc_info)
  File "/home/ivan/PycharmProjects/transito/venv/lib/python3.6/site-packages/sqlalchemy/util/compat.py", line 398, in raise_from_cause
    reraise(type(exception), exception, tb=exc_tb, cause=cause)
  File "/home/ivan/PycharmProjects/transito/venv/lib/python3.6/site-packages/sqlalchemy/util/compat.py", line 152, in reraise
    raise value.with_traceback(tb)
  File "/home/ivan/PycharmProjects/transito/venv/lib/python3.6/site-packages/sqlalchemy/engine/base.py", line 2276, in _wrap_pool_connect
    return fn()
  File "/home/ivan/PycharmProjects/transito/venv/lib/python3.6/site-packages/sqlalchemy/pool/base.py", line 363, in connect
    return _ConnectionFairy._checkout(self)
  File "/home/ivan/PycharmProjects/transito/venv/lib/python3.6/site-packages/sqlalchemy/pool/base.py", line 773, in _checkout
    fairy = _ConnectionRecord.checkout(pool)
  File "/home/ivan/PycharmProjects/transito/venv/lib/python3.6/site-packages/sqlalchemy/pool/base.py", line 492, in checkout
    rec = pool._do_get()
  File "/home/ivan/PycharmProjects/transito/venv/lib/python3.6/site-packages/sqlalchemy/pool/impl.py", line 139, in _do_get
    self._dec_overflow()
  File "/home/ivan/PycharmProjects/transito/venv/lib/python3.6/site-packages/sqlalchemy/util/langhelpers.py", line 68, in __exit__
    compat.reraise(exc_type, exc_value, exc_tb)
  File "/home/ivan/PycharmProjects/transito/venv/lib/python3.6/site-packages/sqlalchemy/util/compat.py", line 153, in reraise
    raise value
  File "/home/ivan/PycharmProjects/transito/venv/lib/python3.6/site-packages/sqlalchemy/pool/impl.py", line 136, in _do_get
    return self._create_connection()
  File "/home/ivan/PycharmProjects/transito/venv/lib/python3.6/site-packages/sqlalchemy/pool/base.py", line 308, in _create_connection
    return _ConnectionRecord(self)
  File "/home/ivan/PycharmProjects/transito/venv/lib/python3.6/site-packages/sqlalchemy/pool/base.py", line 437, in __init__
    self.__connect(first_connect_check=True)
  File "/home/ivan/PycharmProjects/transito/venv/lib/python3.6/site-packages/sqlalchemy/pool/base.py", line 652, in __connect
    connection = pool._invoke_creator(self)
  File "/home/ivan/PycharmProjects/transito/venv/lib/python3.6/site-packages/sqlalchemy/engine/strategies.py", line 114, in connect
    return dialect.connect(*cargs, **cparams)
  File "/home/ivan/PycharmProjects/transito/venv/lib/python3.6/site-packages/sqlalchemy/engine/default.py", line 489, in connect
    return self.dbapi.connect(*cargs, **cparams)
  File "/home/ivan/PycharmProjects/transito/venv/lib/python3.6/site-packages/pymysql/__init__.py", line 94, in Connect
    return Connection(*args, **kwargs)
  File "/home/ivan/PycharmProjects/transito/venv/lib/python3.6/site-packages/pymysql/connections.py", line 325, in __init__
    self.connect()
  File "/home/ivan/PycharmProjects/transito/venv/lib/python3.6/site-packages/pymysql/connections.py", line 599, in connect
    self._request_authentication()
  File "/home/ivan/PycharmProjects/transito/venv/lib/python3.6/site-packages/pymysql/connections.py", line 861, in _request_authentication
    auth_packet = self._read_packet()
  File "/home/ivan/PycharmProjects/transito/venv/lib/python3.6/site-packages/pymysql/connections.py", line 684, in _read_packet
    packet.check_error()
  File "/home/ivan/PycharmProjects/transito/venv/lib/python3.6/site-packages/pymysql/protocol.py", line 220, in check_error
    err.raise_mysql_exception(self._data)
  File "/home/ivan/PycharmProjects/transito/venv/lib/python3.6/site-packages/pymysql/err.py", line 109, in raise_mysql_exception
    raise errorclass(errno, errval)
sqlalchemy.exc.OperationalError: (pymysql.err.OperationalError) (1044, "Access denied for user 'ivan'@'%' to database 'transito'")
(Background on this error at: http://sqlalche.me/e/e3q8)
2020-02-28 11:23 transito     ERROR    (pymysql.err.OperationalError) (1044, "Access denied for user 'ivan'@'%' to database 'transito'")
(Background on this error at: http://sqlalche.me/e/e3q8)
Traceback (most recent call last):
  File "/home/ivan/PycharmProjects/transito/venv/lib/python3.6/site-packages/sqlalchemy/engine/base.py", line 2276, in _wrap_pool_connect
    return fn()
  File "/home/ivan/PycharmProjects/transito/venv/lib/python3.6/site-packages/sqlalchemy/pool/base.py", line 363, in connect
    return _ConnectionFairy._checkout(self)
  File "/home/ivan/PycharmProjects/transito/venv/lib/python3.6/site-packages/sqlalchemy/pool/base.py", line 773, in _checkout
    fairy = _ConnectionRecord.checkout(pool)
  File "/home/ivan/PycharmProjects/transito/venv/lib/python3.6/site-packages/sqlalchemy/pool/base.py", line 492, in checkout
    rec = pool._do_get()
  File "/home/ivan/PycharmProjects/transito/venv/lib/python3.6/site-packages/sqlalchemy/pool/impl.py", line 139, in _do_get
    self._dec_overflow()
  File "/home/ivan/PycharmProjects/transito/venv/lib/python3.6/site-packages/sqlalchemy/util/langhelpers.py", line 68, in __exit__
    compat.reraise(exc_type, exc_value, exc_tb)
  File "/home/ivan/PycharmProjects/transito/venv/lib/python3.6/site-packages/sqlalchemy/util/compat.py", line 153, in reraise
    raise value
  File "/home/ivan/PycharmProjects/transito/venv/lib/python3.6/site-packages/sqlalchemy/pool/impl.py", line 136, in _do_get
    return self._create_connection()
  File "/home/ivan/PycharmProjects/transito/venv/lib/python3.6/site-packages/sqlalchemy/pool/base.py", line 308, in _create_connection
    return _ConnectionRecord(self)
  File "/home/ivan/PycharmProjects/transito/venv/lib/python3.6/site-packages/sqlalchemy/pool/base.py", line 437, in __init__
    self.__connect(first_connect_check=True)
  File "/home/ivan/PycharmProjects/transito/venv/lib/python3.6/site-packages/sqlalchemy/pool/base.py", line 652, in __connect
    connection = pool._invoke_creator(self)
  File "/home/ivan/PycharmProjects/transito/venv/lib/python3.6/site-packages/sqlalchemy/engine/strategies.py", line 114, in connect
    return dialect.connect(*cargs, **cparams)
  File "/home/ivan/PycharmProjects/transito/venv/lib/python3.6/site-packages/sqlalchemy/engine/default.py", line 489, in connect
    return self.dbapi.connect(*cargs, **cparams)
  File "/home/ivan/PycharmProjects/transito/venv/lib/python3.6/site-packages/pymysql/__init__.py", line 94, in Connect
    return Connection(*args, **kwargs)
  File "/home/ivan/PycharmProjects/transito/venv/lib/python3.6/site-packages/pymysql/connections.py", line 325, in __init__
    self.connect()
  File "/home/ivan/PycharmProjects/transito/venv/lib/python3.6/site-packages/pymysql/connections.py", line 599, in connect
    self._request_authentication()
  File "/home/ivan/PycharmProjects/transito/venv/lib/python3.6/site-packages/pymysql/connections.py", line 861, in _request_authentication
    auth_packet = self._read_packet()
  File "/home/ivan/PycharmProjects/transito/venv/lib/python3.6/site-packages/pymysql/connections.py", line 684, in _read_packet
    packet.check_error()
  File "/home/ivan/PycharmProjects/transito/venv/lib/python3.6/site-packages/pymysql/protocol.py", line 220, in check_error
    err.raise_mysql_exception(self._data)
  File "/home/ivan/PycharmProjects/transito/venv/lib/python3.6/site-packages/pymysql/err.py", line 109, in raise_mysql_exception
    raise errorclass(errno, errval)
pymysql.err.OperationalError: (1044, "Access denied for user 'ivan'@'%' to database 'transito'")

The above exception was the direct cause of the following exception:

Traceback (most recent call last):
  File "/home/ivan/PycharmProjects/transito/transito/routes/dta.py", line 19, in dta
    listaanexos = lista_anexos(session, dta_id)
  File "/home/ivan/PycharmProjects/transito/transito/models/dtamanager.py", line 15, in lista_anexos
    return session.query(Anexo).filter(Anexo.dta_id == dta_id).all()
  File "/home/ivan/PycharmProjects/transito/venv/lib/python3.6/site-packages/sqlalchemy/orm/query.py", line 3233, in all
    return list(self)
  File "/home/ivan/PycharmProjects/transito/venv/lib/python3.6/site-packages/sqlalchemy/orm/query.py", line 3389, in __iter__
    return self._execute_and_instances(context)
  File "/home/ivan/PycharmProjects/transito/venv/lib/python3.6/site-packages/sqlalchemy/orm/query.py", line 3411, in _execute_and_instances
    querycontext, self._connection_from_session, close_with_result=True
  File "/home/ivan/PycharmProjects/transito/venv/lib/python3.6/site-packages/sqlalchemy/orm/query.py", line 3426, in _get_bind_args
    mapper=self._bind_mapper(), clause=querycontext.statement, **kw
  File "/home/ivan/PycharmProjects/transito/venv/lib/python3.6/site-packages/sqlalchemy/orm/query.py", line 3404, in _connection_from_session
    conn = self.session.connection(**kw)
  File "/home/ivan/PycharmProjects/transito/venv/lib/python3.6/site-packages/sqlalchemy/orm/session.py", line 1133, in connection
    execution_options=execution_options,
  File "/home/ivan/PycharmProjects/transito/venv/lib/python3.6/site-packages/sqlalchemy/orm/session.py", line 1139, in _connection_for_bind
    engine, execution_options
  File "/home/ivan/PycharmProjects/transito/venv/lib/python3.6/site-packages/sqlalchemy/orm/session.py", line 432, in _connection_for_bind
    conn = bind._contextual_connect()
  File "/home/ivan/PycharmProjects/transito/venv/lib/python3.6/site-packages/sqlalchemy/engine/base.py", line 2242, in _contextual_connect
    self._wrap_pool_connect(self.pool.connect, None),
  File "/home/ivan/PycharmProjects/transito/venv/lib/python3.6/site-packages/sqlalchemy/engine/base.py", line 2280, in _wrap_pool_connect
    e, dialect, self
  File "/home/ivan/PycharmProjects/transito/venv/lib/python3.6/site-packages/sqlalchemy/engine/base.py", line 1547, in _handle_dbapi_exception_noconnection
    util.raise_from_cause(sqlalchemy_exception, exc_info)
  File "/home/ivan/PycharmProjects/transito/venv/lib/python3.6/site-packages/sqlalchemy/util/compat.py", line 398, in raise_from_cause
    reraise(type(exception), exception, tb=exc_tb, cause=cause)
  File "/home/ivan/PycharmProjects/transito/venv/lib/python3.6/site-packages/sqlalchemy/util/compat.py", line 152, in reraise
    raise value.with_traceback(tb)
  File "/home/ivan/PycharmProjects/transito/venv/lib/python3.6/site-packages/sqlalchemy/engine/base.py", line 2276, in _wrap_pool_connect
    return fn()
  File "/home/ivan/PycharmProjects/transito/venv/lib/python3.6/site-packages/sqlalchemy/pool/base.py", line 363, in connect
    return _ConnectionFairy._checkout(self)
  File "/home/ivan/PycharmProjects/transito/venv/lib/python3.6/site-packages/sqlalchemy/pool/base.py", line 773, in _checkout
    fairy = _ConnectionRecord.checkout(pool)
  File "/home/ivan/PycharmProjects/transito/venv/lib/python3.6/site-packages/sqlalchemy/pool/base.py", line 492, in checkout
    rec = pool._do_get()
  File "/home/ivan/PycharmProjects/transito/venv/lib/python3.6/site-packages/sqlalchemy/pool/impl.py", line 139, in _do_get
    self._dec_overflow()
  File "/home/ivan/PycharmProjects/transito/venv/lib/python3.6/site-packages/sqlalchemy/util/langhelpers.py", line 68, in __exit__
    compat.reraise(exc_type, exc_value, exc_tb)
  File "/home/ivan/PycharmProjects/transito/venv/lib/python3.6/site-packages/sqlalchemy/util/compat.py", line 153, in reraise
    raise value
  File "/home/ivan/PycharmProjects/transito/venv/lib/python3.6/site-packages/sqlalchemy/pool/impl.py", line 136, in _do_get
    return self._create_connection()
  File "/home/ivan/PycharmProjects/transito/venv/lib/python3.6/site-packages/sqlalchemy/pool/base.py", line 308, in _create_connection
    return _ConnectionRecord(self)
  File "/home/ivan/PycharmProjects/transito/venv/lib/python3.6/site-packages/sqlalchemy/pool/base.py", line 437, in __init__
    self.__connect(first_connect_check=True)
  File "/home/ivan/PycharmProjects/transito/venv/lib/python3.6/site-packages/sqlalchemy/pool/base.py", line 652, in __connect
    connection = pool._invoke_creator(self)
  File "/home/ivan/PycharmProjects/transito/venv/lib/python3.6/site-packages/sqlalchemy/engine/strategies.py", line 114, in connect
    return dialect.connect(*cargs, **cparams)
  File "/home/ivan/PycharmProjects/transito/venv/lib/python3.6/site-packages/sqlalchemy/engine/default.py", line 489, in connect
    return self.dbapi.connect(*cargs, **cparams)
  File "/home/ivan/PycharmProjects/transito/venv/lib/python3.6/site-packages/pymysql/__init__.py", line 94, in Connect
    return Connection(*args, **kwargs)
  File "/home/ivan/PycharmProjects/transito/venv/lib/python3.6/site-packages/pymysql/connections.py", line 325, in __init__
    self.connect()
  File "/home/ivan/PycharmProjects/transito/venv/lib/python3.6/site-packages/pymysql/connections.py", line 599, in connect
    self._request_authentication()
  File "/home/ivan/PycharmProjects/transito/venv/lib/python3.6/site-packages/pymysql/connections.py", line 861, in _request_authentication
    auth_packet = self._read_packet()
  File "/home/ivan/PycharmProjects/transito/venv/lib/python3.6/site-packages/pymysql/connections.py", line 684, in _read_packet
    packet.check_error()
  File "/home/ivan/PycharmProjects/transito/venv/lib/python3.6/site-packages/pymysql/protocol.py", line 220, in check_error
    err.raise_mysql_exception(self._data)
  File "/home/ivan/PycharmProjects/transito/venv/lib/python3.6/site-packages/pymysql/err.py", line 109, in raise_mysql_exception
    raise errorclass(errno, errval)
sqlalchemy.exc.OperationalError: (pymysql.err.OperationalError) (1044, "Access denied for user 'ivan'@'%' to database 'transito'")
(Background on this error at: http://sqlalche.me/e/e3q8)
2020-02-28 11:23 transito     ERROR    (pymysql.err.OperationalError) (1044, "Access denied for user 'ivan'@'%' to database 'transito'")
(Background on this error at: http://sqlalche.me/e/e3q8)
Traceback (most recent call last):
  File "/home/ivan/PycharmProjects/transito/venv/lib/python3.6/site-packages/sqlalchemy/engine/base.py", line 2276, in _wrap_pool_connect
    return fn()
  File "/home/ivan/PycharmProjects/transito/venv/lib/python3.6/site-packages/sqlalchemy/pool/base.py", line 363, in connect
    return _ConnectionFairy._checkout(self)
  File "/home/ivan/PycharmProjects/transito/venv/lib/python3.6/site-packages/sqlalchemy/pool/base.py", line 773, in _checkout
    fairy = _ConnectionRecord.checkout(pool)
  File "/home/ivan/PycharmProjects/transito/venv/lib/python3.6/site-packages/sqlalchemy/pool/base.py", line 492, in checkout
    rec = pool._do_get()
  File "/home/ivan/PycharmProjects/transito/venv/lib/python3.6/site-packages/sqlalchemy/pool/impl.py", line 139, in _do_get
    self._dec_overflow()
  File "/home/ivan/PycharmProjects/transito/venv/lib/python3.6/site-packages/sqlalchemy/util/langhelpers.py", line 68, in __exit__
    compat.reraise(exc_type, exc_value, exc_tb)
  File "/home/ivan/PycharmProjects/transito/venv/lib/python3.6/site-packages/sqlalchemy/util/compat.py", line 153, in reraise
    raise value
  File "/home/ivan/PycharmProjects/transito/venv/lib/python3.6/site-packages/sqlalchemy/pool/impl.py", line 136, in _do_get
    return self._create_connection()
  File "/home/ivan/PycharmProjects/transito/venv/lib/python3.6/site-packages/sqlalchemy/pool/base.py", line 308, in _create_connection
    return _ConnectionRecord(self)
  File "/home/ivan/PycharmProjects/transito/venv/lib/python3.6/site-packages/sqlalchemy/pool/base.py", line 437, in __init__
    self.__connect(first_connect_check=True)
  File "/home/ivan/PycharmProjects/transito/venv/lib/python3.6/site-packages/sqlalchemy/pool/base.py", line 652, in __connect
    connection = pool._invoke_creator(self)
  File "/home/ivan/PycharmProjects/transito/venv/lib/python3.6/site-packages/sqlalchemy/engine/strategies.py", line 114, in connect
    return dialect.connect(*cargs, **cparams)
  File "/home/ivan/PycharmProjects/transito/venv/lib/python3.6/site-packages/sqlalchemy/engine/default.py", line 489, in connect
    return self.dbapi.connect(*cargs, **cparams)
  File "/home/ivan/PycharmProjects/transito/venv/lib/python3.6/site-packages/pymysql/__init__.py", line 94, in Connect
    return Connection(*args, **kwargs)
  File "/home/ivan/PycharmProjects/transito/venv/lib/python3.6/site-packages/pymysql/connections.py", line 325, in __init__
    self.connect()
  File "/home/ivan/PycharmProjects/transito/venv/lib/python3.6/site-packages/pymysql/connections.py", line 599, in connect
    self._request_authentication()
  File "/home/ivan/PycharmProjects/transito/venv/lib/python3.6/site-packages/pymysql/connections.py", line 861, in _request_authentication
    auth_packet = self._read_packet()
  File "/home/ivan/PycharmProjects/transito/venv/lib/python3.6/site-packages/pymysql/connections.py", line 684, in _read_packet
    packet.check_error()
  File "/home/ivan/PycharmProjects/transito/venv/lib/python3.6/site-packages/pymysql/protocol.py", line 220, in check_error
    err.raise_mysql_exception(self._data)
  File "/home/ivan/PycharmProjects/transito/venv/lib/python3.6/site-packages/pymysql/err.py", line 109, in raise_mysql_exception
    raise errorclass(errno, errval)
pymysql.err.OperationalError: (1044, "Access denied for user 'ivan'@'%' to database 'transito'")

The above exception was the direct cause of the following exception:

Traceback (most recent call last):
  File "/home/ivan/PycharmProjects/transito/transito/routes/dta.py", line 19, in dta
    listaanexos = lista_anexos(session, dta_id)
  File "/home/ivan/PycharmProjects/transito/transito/models/dtamanager.py", line 15, in lista_anexos
    return session.query(Anexo).filter(Anexo.dta_id == dta_id).all()
  File "/home/ivan/PycharmProjects/transito/venv/lib/python3.6/site-packages/sqlalchemy/orm/query.py", line 3233, in all
    return list(self)
  File "/home/ivan/PycharmProjects/transito/venv/lib/python3.6/site-packages/sqlalchemy/orm/query.py", line 3389, in __iter__
    return self._execute_and_instances(context)
  File "/home/ivan/PycharmProjects/transito/venv/lib/python3.6/site-packages/sqlalchemy/orm/query.py", line 3411, in _execute_and_instances
    querycontext, self._connection_from_session, close_with_result=True
  File "/home/ivan/PycharmProjects/transito/venv/lib/python3.6/site-packages/sqlalchemy/orm/query.py", line 3426, in _get_bind_args
    mapper=self._bind_mapper(), clause=querycontext.statement, **kw
  File "/home/ivan/PycharmProjects/transito/venv/lib/python3.6/site-packages/sqlalchemy/orm/query.py", line 3404, in _connection_from_session
    conn = self.session.connection(**kw)
  File "/home/ivan/PycharmProjects/transito/venv/lib/python3.6/site-packages/sqlalchemy/orm/session.py", line 1133, in connection
    execution_options=execution_options,
  File "/home/ivan/PycharmProjects/transito/venv/lib/python3.6/site-packages/sqlalchemy/orm/session.py", line 1139, in _connection_for_bind
    engine, execution_options
  File "/home/ivan/PycharmProjects/transito/venv/lib/python3.6/site-packages/sqlalchemy/orm/session.py", line 432, in _connection_for_bind
    conn = bind._contextual_connect()
  File "/home/ivan/PycharmProjects/transito/venv/lib/python3.6/site-packages/sqlalchemy/engine/base.py", line 2242, in _contextual_connect
    self._wrap_pool_connect(self.pool.connect, None),
  File "/home/ivan/PycharmProjects/transito/venv/lib/python3.6/site-packages/sqlalchemy/engine/base.py", line 2280, in _wrap_pool_connect
    e, dialect, self
  File "/home/ivan/PycharmProjects/transito/venv/lib/python3.6/site-packages/sqlalchemy/engine/base.py", line 1547, in _handle_dbapi_exception_noconnection
    util.raise_from_cause(sqlalchemy_exception, exc_info)
  File "/home/ivan/PycharmProjects/transito/venv/lib/python3.6/site-packages/sqlalchemy/util/compat.py", line 398, in raise_from_cause
    reraise(type(exception), exception, tb=exc_tb, cause=cause)
  File "/home/ivan/PycharmProjects/transito/venv/lib/python3.6/site-packages/sqlalchemy/util/compat.py", line 152, in reraise
    raise value.with_traceback(tb)
  File "/home/ivan/PycharmProjects/transito/venv/lib/python3.6/site-packages/sqlalchemy/engine/base.py", line 2276, in _wrap_pool_connect
    return fn()
  File "/home/ivan/PycharmProjects/transito/venv/lib/python3.6/site-packages/sqlalchemy/pool/base.py", line 363, in connect
    return _ConnectionFairy._checkout(self)
  File "/home/ivan/PycharmProjects/transito/venv/lib/python3.6/site-packages/sqlalchemy/pool/base.py", line 773, in _checkout
    fairy = _ConnectionRecord.checkout(pool)
  File "/home/ivan/PycharmProjects/transito/venv/lib/python3.6/site-packages/sqlalchemy/pool/base.py", line 492, in checkout
    rec = pool._do_get()
  File "/home/ivan/PycharmProjects/transito/venv/lib/python3.6/site-packages/sqlalchemy/pool/impl.py", line 139, in _do_get
    self._dec_overflow()
  File "/home/ivan/PycharmProjects/transito/venv/lib/python3.6/site-packages/sqlalchemy/util/langhelpers.py", line 68, in __exit__
    compat.reraise(exc_type, exc_value, exc_tb)
  File "/home/ivan/PycharmProjects/transito/venv/lib/python3.6/site-packages/sqlalchemy/util/compat.py", line 153, in reraise
    raise value
  File "/home/ivan/PycharmProjects/transito/venv/lib/python3.6/site-packages/sqlalchemy/pool/impl.py", line 136, in _do_get
    return self._create_connection()
  File "/home/ivan/PycharmProjects/transito/venv/lib/python3.6/site-packages/sqlalchemy/pool/base.py", line 308, in _create_connection
    return _ConnectionRecord(self)
  File "/home/ivan/PycharmProjects/transito/venv/lib/python3.6/site-packages/sqlalchemy/pool/base.py", line 437, in __init__
    self.__connect(first_connect_check=True)
  File "/home/ivan/PycharmProjects/transito/venv/lib/python3.6/site-packages/sqlalchemy/pool/base.py", line 652, in __connect
    connection = pool._invoke_creator(self)
  File "/home/ivan/PycharmProjects/transito/venv/lib/python3.6/site-packages/sqlalchemy/engine/strategies.py", line 114, in connect
    return dialect.connect(*cargs, **cparams)
  File "/home/ivan/PycharmProjects/transito/venv/lib/python3.6/site-packages/sqlalchemy/engine/default.py", line 489, in connect
    return self.dbapi.connect(*cargs, **cparams)
  File "/home/ivan/PycharmProjects/transito/venv/lib/python3.6/site-packages/pymysql/__init__.py", line 94, in Connect
    return Connection(*args, **kwargs)
  File "/home/ivan/PycharmProjects/transito/venv/lib/python3.6/site-packages/pymysql/connections.py", line 325, in __init__
    self.connect()
  File "/home/ivan/PycharmProjects/transito/venv/lib/python3.6/site-packages/pymysql/connections.py", line 599, in connect
    self._request_authentication()
  File "/home/ivan/PycharmProjects/transito/venv/lib/python3.6/site-packages/pymysql/connections.py", line 861, in _request_authentication
    auth_packet = self._read_packet()
  File "/home/ivan/PycharmProjects/transito/venv/lib/python3.6/site-packages/pymysql/connections.py", line 684, in _read_packet
    packet.check_error()
  File "/home/ivan/PycharmProjects/transito/venv/lib/python3.6/site-packages/pymysql/protocol.py", line 220, in check_error
    err.raise_mysql_exception(self._data)
  File "/home/ivan/PycharmProjects/transito/venv/lib/python3.6/site-packages/pymysql/err.py", line 109, in raise_mysql_exception
    raise errorclass(errno, errval)
sqlalchemy.exc.OperationalError: (pymysql.err.OperationalError) (1044, "Access denied for user 'ivan'@'%' to database 'transito'")
(Background on this error at: http://sqlalche.me/e/e3q8)
2020-02-28 11:23 transito     ERROR    (pymysql.err.OperationalError) (1044, "Access denied for user 'ivan'@'%' to database 'transito'")
(Background on this error at: http://sqlalche.me/e/e3q8)
Traceback (most recent call last):
  File "/home/ivan/PycharmProjects/transito/venv/lib/python3.6/site-packages/sqlalchemy/engine/base.py", line 2276, in _wrap_pool_connect
    return fn()
  File "/home/ivan/PycharmProjects/transito/venv/lib/python3.6/site-packages/sqlalchemy/pool/base.py", line 363, in connect
    return _ConnectionFairy._checkout(self)
  File "/home/ivan/PycharmProjects/transito/venv/lib/python3.6/site-packages/sqlalchemy/pool/base.py", line 773, in _checkout
    fairy = _ConnectionRecord.checkout(pool)
  File "/home/ivan/PycharmProjects/transito/venv/lib/python3.6/site-packages/sqlalchemy/pool/base.py", line 492, in checkout
    rec = pool._do_get()
  File "/home/ivan/PycharmProjects/transito/venv/lib/python3.6/site-packages/sqlalchemy/pool/impl.py", line 139, in _do_get
    self._dec_overflow()
  File "/home/ivan/PycharmProjects/transito/venv/lib/python3.6/site-packages/sqlalchemy/util/langhelpers.py", line 68, in __exit__
    compat.reraise(exc_type, exc_value, exc_tb)
  File "/home/ivan/PycharmProjects/transito/venv/lib/python3.6/site-packages/sqlalchemy/util/compat.py", line 153, in reraise
    raise value
  File "/home/ivan/PycharmProjects/transito/venv/lib/python3.6/site-packages/sqlalchemy/pool/impl.py", line 136, in _do_get
    return self._create_connection()
  File "/home/ivan/PycharmProjects/transito/venv/lib/python3.6/site-packages/sqlalchemy/pool/base.py", line 308, in _create_connection
    return _ConnectionRecord(self)
  File "/home/ivan/PycharmProjects/transito/venv/lib/python3.6/site-packages/sqlalchemy/pool/base.py", line 437, in __init__
    self.__connect(first_connect_check=True)
  File "/home/ivan/PycharmProjects/transito/venv/lib/python3.6/site-packages/sqlalchemy/pool/base.py", line 652, in __connect
    connection = pool._invoke_creator(self)
  File "/home/ivan/PycharmProjects/transito/venv/lib/python3.6/site-packages/sqlalchemy/engine/strategies.py", line 114, in connect
    return dialect.connect(*cargs, **cparams)
  File "/home/ivan/PycharmProjects/transito/venv/lib/python3.6/site-packages/sqlalchemy/engine/default.py", line 489, in connect
    return self.dbapi.connect(*cargs, **cparams)
  File "/home/ivan/PycharmProjects/transito/venv/lib/python3.6/site-packages/pymysql/__init__.py", line 94, in Connect
    return Connection(*args, **kwargs)
  File "/home/ivan/PycharmProjects/transito/venv/lib/python3.6/site-packages/pymysql/connections.py", line 325, in __init__
    self.connect()
  File "/home/ivan/PycharmProjects/transito/venv/lib/python3.6/site-packages/pymysql/connections.py", line 599, in connect
    self._request_authentication()
  File "/home/ivan/PycharmProjects/transito/venv/lib/python3.6/site-packages/pymysql/connections.py", line 861, in _request_authentication
    auth_packet = self._read_packet()
  File "/home/ivan/PycharmProjects/transito/venv/lib/python3.6/site-packages/pymysql/connections.py", line 684, in _read_packet
    packet.check_error()
  File "/home/ivan/PycharmProjects/transito/venv/lib/python3.6/site-packages/pymysql/protocol.py", line 220, in check_error
    err.raise_mysql_exception(self._data)
  File "/home/ivan/PycharmProjects/transito/venv/lib/python3.6/site-packages/pymysql/err.py", line 109, in raise_mysql_exception
    raise errorclass(errno, errval)
pymysql.err.OperationalError: (1044, "Access denied for user 'ivan'@'%' to database 'transito'")

The above exception was the direct cause of the following exception:

Traceback (most recent call last):
  File "/home/ivan/PycharmProjects/transito/transito/routes/dta.py", line 19, in dta
    listaanexos = lista_anexos(session, dta_id)
  File "/home/ivan/PycharmProjects/transito/transito/models/dtamanager.py", line 15, in lista_anexos
    return session.query(Anexo).filter(Anexo.dta_id == dta_id).all()
  File "/home/ivan/PycharmProjects/transito/venv/lib/python3.6/site-packages/sqlalchemy/orm/query.py", line 3233, in all
    return list(self)
  File "/home/ivan/PycharmProjects/transito/venv/lib/python3.6/site-packages/sqlalchemy/orm/query.py", line 3389, in __iter__
    return self._execute_and_instances(context)
  File "/home/ivan/PycharmProjects/transito/venv/lib/python3.6/site-packages/sqlalchemy/orm/query.py", line 3411, in _execute_and_instances
    querycontext, self._connection_from_session, close_with_result=True
  File "/home/ivan/PycharmProjects/transito/venv/lib/python3.6/site-packages/sqlalchemy/orm/query.py", line 3426, in _get_bind_args
    mapper=self._bind_mapper(), clause=querycontext.statement, **kw
  File "/home/ivan/PycharmProjects/transito/venv/lib/python3.6/site-packages/sqlalchemy/orm/query.py", line 3404, in _connection_from_session
    conn = self.session.connection(**kw)
  File "/home/ivan/PycharmProjects/transito/venv/lib/python3.6/site-packages/sqlalchemy/orm/session.py", line 1133, in connection
    execution_options=execution_options,
  File "/home/ivan/PycharmProjects/transito/venv/lib/python3.6/site-packages/sqlalchemy/orm/session.py", line 1139, in _connection_for_bind
    engine, execution_options
  File "/home/ivan/PycharmProjects/transito/venv/lib/python3.6/site-packages/sqlalchemy/orm/session.py", line 432, in _connection_for_bind
    conn = bind._contextual_connect()
  File "/home/ivan/PycharmProjects/transito/venv/lib/python3.6/site-packages/sqlalchemy/engine/base.py", line 2242, in _contextual_connect
    self._wrap_pool_connect(self.pool.connect, None),
  File "/home/ivan/PycharmProjects/transito/venv/lib/python3.6/site-packages/sqlalchemy/engine/base.py", line 2280, in _wrap_pool_connect
    e, dialect, self
  File "/home/ivan/PycharmProjects/transito/venv/lib/python3.6/site-packages/sqlalchemy/engine/base.py", line 1547, in _handle_dbapi_exception_noconnection
    util.raise_from_cause(sqlalchemy_exception, exc_info)
  File "/home/ivan/PycharmProjects/transito/venv/lib/python3.6/site-packages/sqlalchemy/util/compat.py", line 398, in raise_from_cause
    reraise(type(exception), exception, tb=exc_tb, cause=cause)
  File "/home/ivan/PycharmProjects/transito/venv/lib/python3.6/site-packages/sqlalchemy/util/compat.py", line 152, in reraise
    raise value.with_traceback(tb)
  File "/home/ivan/PycharmProjects/transito/venv/lib/python3.6/site-packages/sqlalchemy/engine/base.py", line 2276, in _wrap_pool_connect
    return fn()
  File "/home/ivan/PycharmProjects/transito/venv/lib/python3.6/site-packages/sqlalchemy/pool/base.py", line 363, in connect
    return _ConnectionFairy._checkout(self)
  File "/home/ivan/PycharmProjects/transito/venv/lib/python3.6/site-packages/sqlalchemy/pool/base.py", line 773, in _checkout
    fairy = _ConnectionRecord.checkout(pool)
  File "/home/ivan/PycharmProjects/transito/venv/lib/python3.6/site-packages/sqlalchemy/pool/base.py", line 492, in checkout
    rec = pool._do_get()
  File "/home/ivan/PycharmProjects/transito/venv/lib/python3.6/site-packages/sqlalchemy/pool/impl.py", line 139, in _do_get
    self._dec_overflow()
  File "/home/ivan/PycharmProjects/transito/venv/lib/python3.6/site-packages/sqlalchemy/util/langhelpers.py", line 68, in __exit__
    compat.reraise(exc_type, exc_value, exc_tb)
  File "/home/ivan/PycharmProjects/transito/venv/lib/python3.6/site-packages/sqlalchemy/util/compat.py", line 153, in reraise
    raise value
  File "/home/ivan/PycharmProjects/transito/venv/lib/python3.6/site-packages/sqlalchemy/pool/impl.py", line 136, in _do_get
    return self._create_connection()
  File "/home/ivan/PycharmProjects/transito/venv/lib/python3.6/site-packages/sqlalchemy/pool/base.py", line 308, in _create_connection
    return _ConnectionRecord(self)
  File "/home/ivan/PycharmProjects/transito/venv/lib/python3.6/site-packages/sqlalchemy/pool/base.py", line 437, in __init__
    self.__connect(first_connect_check=True)
  File "/home/ivan/PycharmProjects/transito/venv/lib/python3.6/site-packages/sqlalchemy/pool/base.py", line 652, in __connect
    connection = pool._invoke_creator(self)
  File "/home/ivan/PycharmProjects/transito/venv/lib/python3.6/site-packages/sqlalchemy/engine/strategies.py", line 114, in connect
    return dialect.connect(*cargs, **cparams)
  File "/home/ivan/PycharmProjects/transito/venv/lib/python3.6/site-packages/sqlalchemy/engine/default.py", line 489, in connect
    return self.dbapi.connect(*cargs, **cparams)
  File "/home/ivan/PycharmProjects/transito/venv/lib/python3.6/site-packages/pymysql/__init__.py", line 94, in Connect
    return Connection(*args, **kwargs)
  File "/home/ivan/PycharmProjects/transito/venv/lib/python3.6/site-packages/pymysql/connections.py", line 325, in __init__
    self.connect()
  File "/home/ivan/PycharmProjects/transito/venv/lib/python3.6/site-packages/pymysql/connections.py", line 599, in connect
    self._request_authentication()
  File "/home/ivan/PycharmProjects/transito/venv/lib/python3.6/site-packages/pymysql/connections.py", line 861, in _request_authentication
    auth_packet = self._read_packet()
  File "/home/ivan/PycharmProjects/transito/venv/lib/python3.6/site-packages/pymysql/connections.py", line 684, in _read_packet
    packet.check_error()
  File "/home/ivan/PycharmProjects/transito/venv/lib/python3.6/site-packages/pymysql/protocol.py", line 220, in check_error
    err.raise_mysql_exception(self._data)
  File "/home/ivan/PycharmProjects/transito/venv/lib/python3.6/site-packages/pymysql/err.py", line 109, in raise_mysql_exception
    raise errorclass(errno, errval)
sqlalchemy.exc.OperationalError: (pymysql.err.OperationalError) (1044, "Access denied for user 'ivan'@'%' to database 'transito'")
(Background on this error at: http://sqlalche.me/e/e3q8)
2020-02-28 11:23 transito     ERROR    (pymysql.err.OperationalError) (1044, "Access denied for user 'ivan'@'%' to database 'transito'")
(Background on this error at: http://sqlalche.me/e/e3q8)
Traceback (most recent call last):
  File "/home/ivan/PycharmProjects/transito/venv/lib/python3.6/site-packages/sqlalchemy/engine/base.py", line 2276, in _wrap_pool_connect
    return fn()
  File "/home/ivan/PycharmProjects/transito/venv/lib/python3.6/site-packages/sqlalchemy/pool/base.py", line 363, in connect
    return _ConnectionFairy._checkout(self)
  File "/home/ivan/PycharmProjects/transito/venv/lib/python3.6/site-packages/sqlalchemy/pool/base.py", line 773, in _checkout
    fairy = _ConnectionRecord.checkout(pool)
  File "/home/ivan/PycharmProjects/transito/venv/lib/python3.6/site-packages/sqlalchemy/pool/base.py", line 492, in checkout
    rec = pool._do_get()
  File "/home/ivan/PycharmProjects/transito/venv/lib/python3.6/site-packages/sqlalchemy/pool/impl.py", line 139, in _do_get
    self._dec_overflow()
  File "/home/ivan/PycharmProjects/transito/venv/lib/python3.6/site-packages/sqlalchemy/util/langhelpers.py", line 68, in __exit__
    compat.reraise(exc_type, exc_value, exc_tb)
  File "/home/ivan/PycharmProjects/transito/venv/lib/python3.6/site-packages/sqlalchemy/util/compat.py", line 153, in reraise
    raise value
  File "/home/ivan/PycharmProjects/transito/venv/lib/python3.6/site-packages/sqlalchemy/pool/impl.py", line 136, in _do_get
    return self._create_connection()
  File "/home/ivan/PycharmProjects/transito/venv/lib/python3.6/site-packages/sqlalchemy/pool/base.py", line 308, in _create_connection
    return _ConnectionRecord(self)
  File "/home/ivan/PycharmProjects/transito/venv/lib/python3.6/site-packages/sqlalchemy/pool/base.py", line 437, in __init__
    self.__connect(first_connect_check=True)
  File "/home/ivan/PycharmProjects/transito/venv/lib/python3.6/site-packages/sqlalchemy/pool/base.py", line 652, in __connect
    connection = pool._invoke_creator(self)
  File "/home/ivan/PycharmProjects/transito/venv/lib/python3.6/site-packages/sqlalchemy/engine/strategies.py", line 114, in connect
    return dialect.connect(*cargs, **cparams)
  File "/home/ivan/PycharmProjects/transito/venv/lib/python3.6/site-packages/sqlalchemy/engine/default.py", line 489, in connect
    return self.dbapi.connect(*cargs, **cparams)
  File "/home/ivan/PycharmProjects/transito/venv/lib/python3.6/site-packages/pymysql/__init__.py", line 94, in Connect
    return Connection(*args, **kwargs)
  File "/home/ivan/PycharmProjects/transito/venv/lib/python3.6/site-packages/pymysql/connections.py", line 325, in __init__
    self.connect()
  File "/home/ivan/PycharmProjects/transito/venv/lib/python3.6/site-packages/pymysql/connections.py", line 599, in connect
    self._request_authentication()
  File "/home/ivan/PycharmProjects/transito/venv/lib/python3.6/site-packages/pymysql/connections.py", line 861, in _request_authentication
    auth_packet = self._read_packet()
  File "/home/ivan/PycharmProjects/transito/venv/lib/python3.6/site-packages/pymysql/connections.py", line 684, in _read_packet
    packet.check_error()
  File "/home/ivan/PycharmProjects/transito/venv/lib/python3.6/site-packages/pymysql/protocol.py", line 220, in check_error
    err.raise_mysql_exception(self._data)
  File "/home/ivan/PycharmProjects/transito/venv/lib/python3.6/site-packages/pymysql/err.py", line 109, in raise_mysql_exception
    raise errorclass(errno, errval)
pymysql.err.OperationalError: (1044, "Access denied for user 'ivan'@'%' to database 'transito'")

The above exception was the direct cause of the following exception:

Traceback (most recent call last):
  File "/home/ivan/PycharmProjects/transito/transito/routes/dta.py", line 19, in dta
    listaanexos = lista_anexos(session, dta_id)
  File "/home/ivan/PycharmProjects/transito/transito/models/dtamanager.py", line 15, in lista_anexos
    return session.query(Anexo).filter(Anexo.dta_id == dta_id).all()
  File "/home/ivan/PycharmProjects/transito/venv/lib/python3.6/site-packages/sqlalchemy/orm/query.py", line 3233, in all
    return list(self)
  File "/home/ivan/PycharmProjects/transito/venv/lib/python3.6/site-packages/sqlalchemy/orm/query.py", line 3389, in __iter__
    return self._execute_and_instances(context)
  File "/home/ivan/PycharmProjects/transito/venv/lib/python3.6/site-packages/sqlalchemy/orm/query.py", line 3411, in _execute_and_instances
    querycontext, self._connection_from_session, close_with_result=True
  File "/home/ivan/PycharmProjects/transito/venv/lib/python3.6/site-packages/sqlalchemy/orm/query.py", line 3426, in _get_bind_args
    mapper=self._bind_mapper(), clause=querycontext.statement, **kw
  File "/home/ivan/PycharmProjects/transito/venv/lib/python3.6/site-packages/sqlalchemy/orm/query.py", line 3404, in _connection_from_session
    conn = self.session.connection(**kw)
  File "/home/ivan/PycharmProjects/transito/venv/lib/python3.6/site-packages/sqlalchemy/orm/session.py", line 1133, in connection
    execution_options=execution_options,
  File "/home/ivan/PycharmProjects/transito/venv/lib/python3.6/site-packages/sqlalchemy/orm/session.py", line 1139, in _connection_for_bind
    engine, execution_options
  File "/home/ivan/PycharmProjects/transito/venv/lib/python3.6/site-packages/sqlalchemy/orm/session.py", line 432, in _connection_for_bind
    conn = bind._contextual_connect()
  File "/home/ivan/PycharmProjects/transito/venv/lib/python3.6/site-packages/sqlalchemy/engine/base.py", line 2242, in _contextual_connect
    self._wrap_pool_connect(self.pool.connect, None),
  File "/home/ivan/PycharmProjects/transito/venv/lib/python3.6/site-packages/sqlalchemy/engine/base.py", line 2280, in _wrap_pool_connect
    e, dialect, self
  File "/home/ivan/PycharmProjects/transito/venv/lib/python3.6/site-packages/sqlalchemy/engine/base.py", line 1547, in _handle_dbapi_exception_noconnection
    util.raise_from_cause(sqlalchemy_exception, exc_info)
  File "/home/ivan/PycharmProjects/transito/venv/lib/python3.6/site-packages/sqlalchemy/util/compat.py", line 398, in raise_from_cause
    reraise(type(exception), exception, tb=exc_tb, cause=cause)
  File "/home/ivan/PycharmProjects/transito/venv/lib/python3.6/site-packages/sqlalchemy/util/compat.py", line 152, in reraise
    raise value.with_traceback(tb)
  File "/home/ivan/PycharmProjects/transito/venv/lib/python3.6/site-packages/sqlalchemy/engine/base.py", line 2276, in _wrap_pool_connect
    return fn()
  File "/home/ivan/PycharmProjects/transito/venv/lib/python3.6/site-packages/sqlalchemy/pool/base.py", line 363, in connect
    return _ConnectionFairy._checkout(self)
  File "/home/ivan/PycharmProjects/transito/venv/lib/python3.6/site-packages/sqlalchemy/pool/base.py", line 773, in _checkout
    fairy = _ConnectionRecord.checkout(pool)
  File "/home/ivan/PycharmProjects/transito/venv/lib/python3.6/site-packages/sqlalchemy/pool/base.py", line 492, in checkout
    rec = pool._do_get()
  File "/home/ivan/PycharmProjects/transito/venv/lib/python3.6/site-packages/sqlalchemy/pool/impl.py", line 139, in _do_get
    self._dec_overflow()
  File "/home/ivan/PycharmProjects/transito/venv/lib/python3.6/site-packages/sqlalchemy/util/langhelpers.py", line 68, in __exit__
    compat.reraise(exc_type, exc_value, exc_tb)
  File "/home/ivan/PycharmProjects/transito/venv/lib/python3.6/site-packages/sqlalchemy/util/compat.py", line 153, in reraise
    raise value
  File "/home/ivan/PycharmProjects/transito/venv/lib/python3.6/site-packages/sqlalchemy/pool/impl.py", line 136, in _do_get
    return self._create_connection()
  File "/home/ivan/PycharmProjects/transito/venv/lib/python3.6/site-packages/sqlalchemy/pool/base.py", line 308, in _create_connection
    return _ConnectionRecord(self)
  File "/home/ivan/PycharmProjects/transito/venv/lib/python3.6/site-packages/sqlalchemy/pool/base.py", line 437, in __init__
    self.__connect(first_connect_check=True)
  File "/home/ivan/PycharmProjects/transito/venv/lib/python3.6/site-packages/sqlalchemy/pool/base.py", line 652, in __connect
    connection = pool._invoke_creator(self)
  File "/home/ivan/PycharmProjects/transito/venv/lib/python3.6/site-packages/sqlalchemy/engine/strategies.py", line 114, in connect
    return dialect.connect(*cargs, **cparams)
  File "/home/ivan/PycharmProjects/transito/venv/lib/python3.6/site-packages/sqlalchemy/engine/default.py", line 489, in connect
    return self.dbapi.connect(*cargs, **cparams)
  File "/home/ivan/PycharmProjects/transito/venv/lib/python3.6/site-packages/pymysql/__init__.py", line 94, in Connect
    return Connection(*args, **kwargs)
  File "/home/ivan/PycharmProjects/transito/venv/lib/python3.6/site-packages/pymysql/connections.py", line 325, in __init__
    self.connect()
  File "/home/ivan/PycharmProjects/transito/venv/lib/python3.6/site-packages/pymysql/connections.py", line 599, in connect
    self._request_authentication()
  File "/home/ivan/PycharmProjects/transito/venv/lib/python3.6/site-packages/pymysql/connections.py", line 861, in _request_authentication
    auth_packet = self._read_packet()
  File "/home/ivan/PycharmProjects/transito/venv/lib/python3.6/site-packages/pymysql/connections.py", line 684, in _read_packet
    packet.check_error()
  File "/home/ivan/PycharmProjects/transito/venv/lib/python3.6/site-packages/pymysql/protocol.py", line 220, in check_error
    err.raise_mysql_exception(self._data)
  File "/home/ivan/PycharmProjects/transito/venv/lib/python3.6/site-packages/pymysql/err.py", line 109, in raise_mysql_exception
    raise errorclass(errno, errval)
sqlalchemy.exc.OperationalError: (pymysql.err.OperationalError) (1044, "Access denied for user 'ivan'@'%' to database 'transito'")
(Background on this error at: http://sqlalche.me/e/e3q8)
2020-02-28 11:23 transito     ERROR    (pymysql.err.OperationalError) (1044, "Access denied for user 'ivan'@'%' to database 'transito'")
(Background on this error at: http://sqlalche.me/e/e3q8)
Traceback (most recent call last):
  File "/home/ivan/PycharmProjects/transito/venv/lib/python3.6/site-packages/sqlalchemy/engine/base.py", line 2276, in _wrap_pool_connect
    return fn()
  File "/home/ivan/PycharmProjects/transito/venv/lib/python3.6/site-packages/sqlalchemy/pool/base.py", line 363, in connect
    return _ConnectionFairy._checkout(self)
  File "/home/ivan/PycharmProjects/transito/venv/lib/python3.6/site-packages/sqlalchemy/pool/base.py", line 773, in _checkout
    fairy = _ConnectionRecord.checkout(pool)
  File "/home/ivan/PycharmProjects/transito/venv/lib/python3.6/site-packages/sqlalchemy/pool/base.py", line 492, in checkout
    rec = pool._do_get()
  File "/home/ivan/PycharmProjects/transito/venv/lib/python3.6/site-packages/sqlalchemy/pool/impl.py", line 139, in _do_get
    self._dec_overflow()
  File "/home/ivan/PycharmProjects/transito/venv/lib/python3.6/site-packages/sqlalchemy/util/langhelpers.py", line 68, in __exit__
    compat.reraise(exc_type, exc_value, exc_tb)
  File "/home/ivan/PycharmProjects/transito/venv/lib/python3.6/site-packages/sqlalchemy/util/compat.py", line 153, in reraise
    raise value
  File "/home/ivan/PycharmProjects/transito/venv/lib/python3.6/site-packages/sqlalchemy/pool/impl.py", line 136, in _do_get
    return self._create_connection()
  File "/home/ivan/PycharmProjects/transito/venv/lib/python3.6/site-packages/sqlalchemy/pool/base.py", line 308, in _create_connection
    return _ConnectionRecord(self)
  File "/home/ivan/PycharmProjects/transito/venv/lib/python3.6/site-packages/sqlalchemy/pool/base.py", line 437, in __init__
    self.__connect(first_connect_check=True)
  File "/home/ivan/PycharmProjects/transito/venv/lib/python3.6/site-packages/sqlalchemy/pool/base.py", line 652, in __connect
    connection = pool._invoke_creator(self)
  File "/home/ivan/PycharmProjects/transito/venv/lib/python3.6/site-packages/sqlalchemy/engine/strategies.py", line 114, in connect
    return dialect.connect(*cargs, **cparams)
  File "/home/ivan/PycharmProjects/transito/venv/lib/python3.6/site-packages/sqlalchemy/engine/default.py", line 489, in connect
    return self.dbapi.connect(*cargs, **cparams)
  File "/home/ivan/PycharmProjects/transito/venv/lib/python3.6/site-packages/pymysql/__init__.py", line 94, in Connect
    return Connection(*args, **kwargs)
  File "/home/ivan/PycharmProjects/transito/venv/lib/python3.6/site-packages/pymysql/connections.py", line 325, in __init__
    self.connect()
  File "/home/ivan/PycharmProjects/transito/venv/lib/python3.6/site-packages/pymysql/connections.py", line 599, in connect
    self._request_authentication()
  File "/home/ivan/PycharmProjects/transito/venv/lib/python3.6/site-packages/pymysql/connections.py", line 861, in _request_authentication
    auth_packet = self._read_packet()
  File "/home/ivan/PycharmProjects/transito/venv/lib/python3.6/site-packages/pymysql/connections.py", line 684, in _read_packet
    packet.check_error()
  File "/home/ivan/PycharmProjects/transito/venv/lib/python3.6/site-packages/pymysql/protocol.py", line 220, in check_error
    err.raise_mysql_exception(self._data)
  File "/home/ivan/PycharmProjects/transito/venv/lib/python3.6/site-packages/pymysql/err.py", line 109, in raise_mysql_exception
    raise errorclass(errno, errval)
pymysql.err.OperationalError: (1044, "Access denied for user 'ivan'@'%' to database 'transito'")

The above exception was the direct cause of the following exception:

Traceback (most recent call last):
  File "/home/ivan/PycharmProjects/transito/transito/routes/dta.py", line 19, in dta
    listaanexos = lista_anexos(session, dta_id)
  File "/home/ivan/PycharmProjects/transito/transito/models/dtamanager.py", line 15, in lista_anexos
    return session.query(Anexo).filter(Anexo.dta_id == dta_id).all()
  File "/home/ivan/PycharmProjects/transito/venv/lib/python3.6/site-packages/sqlalchemy/orm/query.py", line 3233, in all
    return list(self)
  File "/home/ivan/PycharmProjects/transito/venv/lib/python3.6/site-packages/sqlalchemy/orm/query.py", line 3389, in __iter__
    return self._execute_and_instances(context)
  File "/home/ivan/PycharmProjects/transito/venv/lib/python3.6/site-packages/sqlalchemy/orm/query.py", line 3411, in _execute_and_instances
    querycontext, self._connection_from_session, close_with_result=True
  File "/home/ivan/PycharmProjects/transito/venv/lib/python3.6/site-packages/sqlalchemy/orm/query.py", line 3426, in _get_bind_args
    mapper=self._bind_mapper(), clause=querycontext.statement, **kw
  File "/home/ivan/PycharmProjects/transito/venv/lib/python3.6/site-packages/sqlalchemy/orm/query.py", line 3404, in _connection_from_session
    conn = self.session.connection(**kw)
  File "/home/ivan/PycharmProjects/transito/venv/lib/python3.6/site-packages/sqlalchemy/orm/session.py", line 1133, in connection
    execution_options=execution_options,
  File "/home/ivan/PycharmProjects/transito/venv/lib/python3.6/site-packages/sqlalchemy/orm/session.py", line 1139, in _connection_for_bind
    engine, execution_options
  File "/home/ivan/PycharmProjects/transito/venv/lib/python3.6/site-packages/sqlalchemy/orm/session.py", line 432, in _connection_for_bind
    conn = bind._contextual_connect()
  File "/home/ivan/PycharmProjects/transito/venv/lib/python3.6/site-packages/sqlalchemy/engine/base.py", line 2242, in _contextual_connect
    self._wrap_pool_connect(self.pool.connect, None),
  File "/home/ivan/PycharmProjects/transito/venv/lib/python3.6/site-packages/sqlalchemy/engine/base.py", line 2280, in _wrap_pool_connect
    e, dialect, self
  File "/home/ivan/PycharmProjects/transito/venv/lib/python3.6/site-packages/sqlalchemy/engine/base.py", line 1547, in _handle_dbapi_exception_noconnection
    util.raise_from_cause(sqlalchemy_exception, exc_info)
  File "/home/ivan/PycharmProjects/transito/venv/lib/python3.6/site-packages/sqlalchemy/util/compat.py", line 398, in raise_from_cause
    reraise(type(exception), exception, tb=exc_tb, cause=cause)
  File "/home/ivan/PycharmProjects/transito/venv/lib/python3.6/site-packages/sqlalchemy/util/compat.py", line 152, in reraise
    raise value.with_traceback(tb)
  File "/home/ivan/PycharmProjects/transito/venv/lib/python3.6/site-packages/sqlalchemy/engine/base.py", line 2276, in _wrap_pool_connect
    return fn()
  File "/home/ivan/PycharmProjects/transito/venv/lib/python3.6/site-packages/sqlalchemy/pool/base.py", line 363, in connect
    return _ConnectionFairy._checkout(self)
  File "/home/ivan/PycharmProjects/transito/venv/lib/python3.6/site-packages/sqlalchemy/pool/base.py", line 773, in _checkout
    fairy = _ConnectionRecord.checkout(pool)
  File "/home/ivan/PycharmProjects/transito/venv/lib/python3.6/site-packages/sqlalchemy/pool/base.py", line 492, in checkout
    rec = pool._do_get()
  File "/home/ivan/PycharmProjects/transito/venv/lib/python3.6/site-packages/sqlalchemy/pool/impl.py", line 139, in _do_get
    self._dec_overflow()
  File "/home/ivan/PycharmProjects/transito/venv/lib/python3.6/site-packages/sqlalchemy/util/langhelpers.py", line 68, in __exit__
    compat.reraise(exc_type, exc_value, exc_tb)
  File "/home/ivan/PycharmProjects/transito/venv/lib/python3.6/site-packages/sqlalchemy/util/compat.py", line 153, in reraise
    raise value
  File "/home/ivan/PycharmProjects/transito/venv/lib/python3.6/site-packages/sqlalchemy/pool/impl.py", line 136, in _do_get
    return self._create_connection()
  File "/home/ivan/PycharmProjects/transito/venv/lib/python3.6/site-packages/sqlalchemy/pool/base.py", line 308, in _create_connection
    return _ConnectionRecord(self)
  File "/home/ivan/PycharmProjects/transito/venv/lib/python3.6/site-packages/sqlalchemy/pool/base.py", line 437, in __init__
    self.__connect(first_connect_check=True)
  File "/home/ivan/PycharmProjects/transito/venv/lib/python3.6/site-packages/sqlalchemy/pool/base.py", line 652, in __connect
    connection = pool._invoke_creator(self)
  File "/home/ivan/PycharmProjects/transito/venv/lib/python3.6/site-packages/sqlalchemy/engine/strategies.py", line 114, in connect
    return dialect.connect(*cargs, **cparams)
  File "/home/ivan/PycharmProjects/transito/venv/lib/python3.6/site-packages/sqlalchemy/engine/default.py", line 489, in connect
    return self.dbapi.connect(*cargs, **cparams)
  File "/home/ivan/PycharmProjects/transito/venv/lib/python3.6/site-packages/pymysql/__init__.py", line 94, in Connect
    return Connection(*args, **kwargs)
  File "/home/ivan/PycharmProjects/transito/venv/lib/python3.6/site-packages/pymysql/connections.py", line 325, in __init__
    self.connect()
  File "/home/ivan/PycharmProjects/transito/venv/lib/python3.6/site-packages/pymysql/connections.py", line 599, in connect
    self._request_authentication()
  File "/home/ivan/PycharmProjects/transito/venv/lib/python3.6/site-packages/pymysql/connections.py", line 861, in _request_authentication
    auth_packet = self._read_packet()
  File "/home/ivan/PycharmProjects/transito/venv/lib/python3.6/site-packages/pymysql/connections.py", line 684, in _read_packet
    packet.check_error()
  File "/home/ivan/PycharmProjects/transito/venv/lib/python3.6/site-packages/pymysql/protocol.py", line 220, in check_error
    err.raise_mysql_exception(self._data)
  File "/home/ivan/PycharmProjects/transito/venv/lib/python3.6/site-packages/pymysql/err.py", line 109, in raise_mysql_exception
    raise errorclass(errno, errval)
sqlalchemy.exc.OperationalError: (pymysql.err.OperationalError) (1044, "Access denied for user 'ivan'@'%' to database 'transito'")
(Background on this error at: http://sqlalche.me/e/e3q8)
2020-02-28 11:24 transito     ERROR    (pymysql.err.ProgrammingError) (1146, "Table 'transito.dta_anexos' doesn't exist")
[SQL: SELECT dta_anexos.id AS dta_anexos_id, dta_anexos.dta_id AS dta_anexos_dta_id, dta_anexos.nomearquivo AS dta_anexos_nomearquivo, dta_anexos.observacoes AS dta_anexos_observacoes, dta_anexos.temconteudo AS dta_anexos_temconteudo, dta_anexos.qualidade AS dta_anexos_qualidade, dta_anexos.tipoconteudo AS dta_anexos_tipoconteudo 
FROM dta_anexos 
WHERE dta_anexos.dta_id = %(dta_id_1)s]
[parameters: {'dta_id_1': 1}]
(Background on this error at: http://sqlalche.me/e/f405)
Traceback (most recent call last):
  File "/home/ivan/PycharmProjects/transito/venv/lib/python3.6/site-packages/sqlalchemy/engine/base.py", line 1246, in _execute_context
    cursor, statement, parameters, context
  File "/home/ivan/PycharmProjects/transito/venv/lib/python3.6/site-packages/sqlalchemy/engine/default.py", line 588, in do_execute
    cursor.execute(statement, parameters)
  File "/home/ivan/PycharmProjects/transito/venv/lib/python3.6/site-packages/pymysql/cursors.py", line 170, in execute
    result = self._query(query)
  File "/home/ivan/PycharmProjects/transito/venv/lib/python3.6/site-packages/pymysql/cursors.py", line 328, in _query
    conn.query(q)
  File "/home/ivan/PycharmProjects/transito/venv/lib/python3.6/site-packages/pymysql/connections.py", line 517, in query
    self._affected_rows = self._read_query_result(unbuffered=unbuffered)
  File "/home/ivan/PycharmProjects/transito/venv/lib/python3.6/site-packages/pymysql/connections.py", line 732, in _read_query_result
    result.read()
  File "/home/ivan/PycharmProjects/transito/venv/lib/python3.6/site-packages/pymysql/connections.py", line 1075, in read
    first_packet = self.connection._read_packet()
  File "/home/ivan/PycharmProjects/transito/venv/lib/python3.6/site-packages/pymysql/connections.py", line 684, in _read_packet
    packet.check_error()
  File "/home/ivan/PycharmProjects/transito/venv/lib/python3.6/site-packages/pymysql/protocol.py", line 220, in check_error
    err.raise_mysql_exception(self._data)
  File "/home/ivan/PycharmProjects/transito/venv/lib/python3.6/site-packages/pymysql/err.py", line 109, in raise_mysql_exception
    raise errorclass(errno, errval)
pymysql.err.ProgrammingError: (1146, "Table 'transito.dta_anexos' doesn't exist")

The above exception was the direct cause of the following exception:

Traceback (most recent call last):
  File "/home/ivan/PycharmProjects/transito/transito/routes/dta.py", line 19, in dta
    listaanexos = lista_anexos(session, dta_id)
  File "/home/ivan/PycharmProjects/transito/transito/models/dtamanager.py", line 15, in lista_anexos
    return session.query(Anexo).filter(Anexo.dta_id == dta_id).all()
  File "/home/ivan/PycharmProjects/transito/venv/lib/python3.6/site-packages/sqlalchemy/orm/query.py", line 3233, in all
    return list(self)
  File "/home/ivan/PycharmProjects/transito/venv/lib/python3.6/site-packages/sqlalchemy/orm/query.py", line 3389, in __iter__
    return self._execute_and_instances(context)
  File "/home/ivan/PycharmProjects/transito/venv/lib/python3.6/site-packages/sqlalchemy/orm/query.py", line 3414, in _execute_and_instances
    result = conn.execute(querycontext.statement, self._params)
  File "/home/ivan/PycharmProjects/transito/venv/lib/python3.6/site-packages/sqlalchemy/engine/base.py", line 982, in execute
    return meth(self, multiparams, params)
  File "/home/ivan/PycharmProjects/transito/venv/lib/python3.6/site-packages/sqlalchemy/sql/elements.py", line 293, in _execute_on_connection
    return connection._execute_clauseelement(self, multiparams, params)
  File "/home/ivan/PycharmProjects/transito/venv/lib/python3.6/site-packages/sqlalchemy/engine/base.py", line 1101, in _execute_clauseelement
    distilled_params,
  File "/home/ivan/PycharmProjects/transito/venv/lib/python3.6/site-packages/sqlalchemy/engine/base.py", line 1250, in _execute_context
    e, statement, parameters, cursor, context
  File "/home/ivan/PycharmProjects/transito/venv/lib/python3.6/site-packages/sqlalchemy/engine/base.py", line 1476, in _handle_dbapi_exception
    util.raise_from_cause(sqlalchemy_exception, exc_info)
  File "/home/ivan/PycharmProjects/transito/venv/lib/python3.6/site-packages/sqlalchemy/util/compat.py", line 398, in raise_from_cause
    reraise(type(exception), exception, tb=exc_tb, cause=cause)
  File "/home/ivan/PycharmProjects/transito/venv/lib/python3.6/site-packages/sqlalchemy/util/compat.py", line 152, in reraise
    raise value.with_traceback(tb)
  File "/home/ivan/PycharmProjects/transito/venv/lib/python3.6/site-packages/sqlalchemy/engine/base.py", line 1246, in _execute_context
    cursor, statement, parameters, context
  File "/home/ivan/PycharmProjects/transito/venv/lib/python3.6/site-packages/sqlalchemy/engine/default.py", line 588, in do_execute
    cursor.execute(statement, parameters)
  File "/home/ivan/PycharmProjects/transito/venv/lib/python3.6/site-packages/pymysql/cursors.py", line 170, in execute
    result = self._query(query)
  File "/home/ivan/PycharmProjects/transito/venv/lib/python3.6/site-packages/pymysql/cursors.py", line 328, in _query
    conn.query(q)
  File "/home/ivan/PycharmProjects/transito/venv/lib/python3.6/site-packages/pymysql/connections.py", line 517, in query
    self._affected_rows = self._read_query_result(unbuffered=unbuffered)
  File "/home/ivan/PycharmProjects/transito/venv/lib/python3.6/site-packages/pymysql/connections.py", line 732, in _read_query_result
    result.read()
  File "/home/ivan/PycharmProjects/transito/venv/lib/python3.6/site-packages/pymysql/connections.py", line 1075, in read
    first_packet = self.connection._read_packet()
  File "/home/ivan/PycharmProjects/transito/venv/lib/python3.6/site-packages/pymysql/connections.py", line 684, in _read_packet
    packet.check_error()
  File "/home/ivan/PycharmProjects/transito/venv/lib/python3.6/site-packages/pymysql/protocol.py", line 220, in check_error
    err.raise_mysql_exception(self._data)
  File "/home/ivan/PycharmProjects/transito/venv/lib/python3.6/site-packages/pymysql/err.py", line 109, in raise_mysql_exception
    raise errorclass(errno, errval)
sqlalchemy.exc.ProgrammingError: (pymysql.err.ProgrammingError) (1146, "Table 'transito.dta_anexos' doesn't exist")
[SQL: SELECT dta_anexos.id AS dta_anexos_id, dta_anexos.dta_id AS dta_anexos_dta_id, dta_anexos.nomearquivo AS dta_anexos_nomearquivo, dta_anexos.observacoes AS dta_anexos_observacoes, dta_anexos.temconteudo AS dta_anexos_temconteudo, dta_anexos.qualidade AS dta_anexos_qualidade, dta_anexos.tipoconteudo AS dta_anexos_tipoconteudo 
FROM dta_anexos 
WHERE dta_anexos.dta_id = %(dta_id_1)s]
[parameters: {'dta_id_1': 1}]
(Background on this error at: http://sqlalche.me/e/f405)
